Workbook

Sheet load-displacament
A1: Zero days | B1: SAMPLE 15 | F1: GOM | K1: SAMPLE 14 | O1: GOM | T1: SAMPLE 13 | X1: GOM | AC1: SAMPLE 12 | AG1: GOM | AL1: SAMPLE 11 | AP1: GOM | AU1: 15 DAYS NO DRYED> | AV1: SAMPLE 10 | AZ1: GOM | BE1: SAMPLE 9 | BI1: GOM | BN1: SAMPLE 8 | BR1: GOM | BW1: SAMPLE 7 | CA1: GOM | CF1: SAMPLE 6 | CJ1: GOM | CO1: 15 DAYS DRYED> | CP1: SAMPLE 5 | CT1: GOM | CY1: SAMPLE 4 | DC1: GOM | DH1: SAMPLE 3 | DL1: GOM | DQ1: SAMPLE 2 | DU1: GOM | DZ1: SAMPLE 1 | ED1: GOM
C2: Horário [s] | D2: Extensão [mm] | E2: Carga [N] | F2: Time[s] | G2: strain | H2: LOAD | I2: STRESS | J2: 0.0011026 | L2: Horário [s] | M2: Extensão [mm] | N2: Carga [N] | O2: Time[s] | P2: strain | Q2: LOAD | R2: STRESS | S2: -0.0033388 | U2: Horário [s] | V2: Extensão [mm] | W2: Carga [N] | X2: Time[s] | Y2: strain | Z2: LOAD | AA2: STRESS | AB2: -0.2375 | AD2: Horário [s] | AE2: Extensão [mm] | AF2: Carga [N] | AG2: Time[s] | AH2: strain | AI2: LOAD | AJ2: STRESS | AK2: -0.6074866 | AM2: Horário [s] | AN2: Extensão [mm] | AO2: Carga [N] | AP2: Time[s] | AQ2: strain | AR2: LOAD | AS2: STRESS | AT2: -0.0201888 | AW2: Horário [s] | AX2: Extensão [mm] | AY2: Carga [N] | AZ2: Time[s] | BA2: strain | BB2: LOAD | BC2: STRESS | BD2: -0.0044352 | BF2: Horário [s] | BG2: Extensão [mm] | BH2: Carga [N] | BI2: Time[s] | BJ2: strain | BK2: LOAD | BL2: STRESS | BM2: -0.0422068 | BO2: Horário [s] | BP2: Extensão [mm] | BQ2: Carga [N] | BR2: Time[s] | BS2: strain | BT2: LOAD | BU2: STRESS | BV2: -0.7180466 | BX2: Horário [s] | BY2: Extensão [mm] | BZ2: Carga [N] | CA2: Time[s] | CB2: strain | CC2: LOAD | CD2: STRESS | CE2: -0.033694 | CG2: Horário [s] | CH2: Extensão [mm] | CI2: Carga [N] | CJ2: Time[s] | CK2: strain | CL2: LOAD | CM2: STRESS | CN2: -0.0309374 | CQ2: Horário [s] | CR2: Extensão [mm] | CS2: Carga [N] | CT2: Time[s] | CU2: strain | CV2: LOAD | CW2: STRESS | CX2: -0.7842374 | CZ2: Horário [s] | DA2: Extensão [mm] | DB2: Carga [N] | DC2: Time[s] | DD2: strain | DE2: LOAD | DF2: STRESS | DG2: -0.0391312 | DI2: Horário [s] | DJ2: Extensão [mm] | DK2: Carga [N] | DL2: Time[s] | DM2: strain | DN2: LOAD | DO2: STRESS | DP2: -0.0625486 | DR2: Horário [s] | DS2: Extensão [mm] | DT2: Carga [N] | DU2: Time[s] | DV2: strain | DW2: LOAD | DX2: STRESS | DY2: -0.0500462 | EA2: Horário [s] | EB2: Extensão [mm] | EC2: Carga [N] | ED2: Time[s] | EE2: strain | EF2: LOAD | EG2: STRESS | EH2: -0.0500462
B3: 1 | C3: 0 | D3: 0 | E3: 0.05513 | F3: 0 | G3: 0 | H3: =INDEX($E:$E,MATCH(F3,$C:$C,1)) -> 0.05513 | I3: =H3/50 -J$2 -> 0 | K3: 1 | L3: 0 | M3: 0 | N3: -0.16694 | O3: 0 | P3: 0 | Q3: =INDEX($N:$N,MATCH(O3,$L:$L,1)) -> -0.16694 | R3: =Q3/50 -S$2 -> 0 | T3: 1 | U3: 0 | V3: 0 | W3: -11.875 | X3: 0 | Y3: 0 | Z3: =INDEX($W:$W,MATCH(X3,$U:$U,1)) -> -11.875 | AA3: =Z3/50 -AB$2 -> 0 | AC3: 1 | AD3: 0 | AE3: 0 | AF3: -30.37433 | AG3: 0 | AH3: 0 | AI3: =INDEX($AF:$AF,MATCH(AG3,$AD:$AD,1)) -> -30.37433 | AJ3: =AI3/50 -AK$2 -> 0 | AL3: 1 | AM3: 0 | AN3: 0 | AO3: -1.00944 | AP3: 0 | AQ3: 0 | AR3: =INDEX($AO:$AO,MATCH(AP3,$AM:$AM,1)) -> -1.00944 | AS3: =AR3/50 -AT$2 -> 0 | AV3: 1 | AW3: 0 | AX3: 0 | AY3: -0.22176 | AZ3: 0 | BA3: 0 | BB3: =INDEX($AY:$AY,MATCH(AZ3,$AW:$AW,1)) -> -0.22176 | BC3: =BB3/50 -BD$2 -> 0 | BE3: 1 | BF3: 0 | BG3: 0 | BH3: -2.11034 | BI3: 0 | BJ3: 0 | BK3: =INDEX($BH:$BH,MATCH(BI3,$BF:$BF,1)) -> -2.11034 | BL3: =BK3/50 -BM$2 -> 0 | BN3: 1 | BO3: 0 | BP3: 0 | BQ3: -35.90233 | BR3: 0 | BS3: 0 | BT3: =INDEX($BQ:$BQ,MATCH(BR3,$BO:$BO,1)) -> -35.90233 | BU3: =BT3/50 -BV$2 -> 0 | BW3: 1 | BX3: 0 | BY3: 0 | BZ3: -1.6847 | CA3: 0 | CB3: 0 | CC3: =INDEX($BZ:$BZ,MATCH(CA3,$BX:$BX,1)) -> -1.6847 | CD3: =CC3/50 -CE$2 -> 0 | CF3: 1 | CG3: 0 | CH3: 0 | CI3: -1.54687 | CJ3: 0 | CK3: 0 | CL3: =INDEX($CI:$CI,MATCH(CJ3,$CG:$CG,1)) -> -1.54687 | CM3: =CL3/50 -CN$2 -> 0 | CP3: 1 | CQ3: 0 | CR3: 0 | CS3: -39.21187 | CT3: 0 | CU3: 0 | CV3: =INDEX($CS:$CS,MATCH(CT3,$CQ:$CQ,1)) -> -39.21187 | CW3: =CV3/50 -CX$2 -> 0 | CY3: 1 | CZ3: 0 | DA3: 0 | DB3: -1.95656 | DC3: 0 | DD3: 0 | DE3: =INDEX($DB:$DB,MATCH(DC3,$CZ:$CZ,1)) -> -1.95656 | DF3: =DE3/50 -DG$2 -> 0 | DH3: 1 | DI3: 0 | DJ3: 0 | DK3: -3.12743 | DL3: 0 | DM3: 0 | DN3: =INDEX($DK:$DK,MATCH(DL3,$DI:$DI,1)) -> -3.12743 | DO3: =DN3/50 -DP$2 -> 0 | DQ3: 1 | DR3: 0 | DS3: 0 | DT3: -2.50231 | DU3: 0 | DV3: 0 | DW3: =INDEX($DT:$DT,MATCH(DU3,$DR:$DR,1)) -> -2.50231 | DX3: =DW3/50 -DY$2 -> 0 | DZ3: 1 | EA3: 0 | EB3: 0 | EC3: -2.40483 | ED3: 0 | EE3: 0 | EF3: =INDEX($DT:$DT,MATCH(ED3,$DR:$DR,1)) -> -2.50231 | EG3: =EF3/50 -EH$2 -> 0
B4: 2 | C4: 0.1 | D4: 0.00159 | E4: 2.86799 | F4: 5 | G4: 0.06086 | H4: =INDEX($E:$E,MATCH(F4,$C:$C,1)) -> 590.17627 | I4: =H4/50 -J$2 -> 11.802423 | K4: 2 | L4: 0.1 | M4: 0.00188 | N4: 5.82101 | O4: 5 | P4: 0.062403 | Q4: =INDEX($N:$N,MATCH(O4,$L:$L,1)) -> 558.47546 | R4: =Q4/50 -S$2 -> 11.172848 | T4: 2 | U4: 0.1 | V4: 0.00165 | W4: -8.46249 | X4: 5 | Y4: 0.075917 | Z4: =INDEX($W:$W,MATCH(X4,$U:$U,1)) -> 546.66956 | AA4: =Z4/50 -AB$2 -> 11.170891 | AC4: 2 | AD4: 0.1 | AE4: 0.00183 | AF4: -24.76331 | AG4: 5 | AH4: 0.067043 | AI4: =INDEX($AF:$AF,MATCH(AG4,$AD:$AD,1)) -> 523.71228 | AJ4: =AI4/50 -AK$2 -> 11.081732 | AL4: 2 | AM4: 0.1 | AN4: 0.00147 | AO4: 0.73422 | AP4: 5 | AQ4: 0.062038 | AR4: =INDEX($AO:$AO,MATCH(AP4,$AM:$AM,1)) -> 533.14392 | AS4: =AR4/50 -AT$2 -> 10.683067 | AV4: 2 | AW4: 0.1 | AX4: 0.00188 | AY4: 5.60883 | AZ4: 5 | BA4: 0.06953 | BB4: =INDEX($AY:$AY,MATCH(AZ4,$AW:$AW,1)) -> 543.9176 | BC4: =BB4/50 -BD$2 -> 10.882787 | BE4: 2 | BF4: 0.1 | BG4: 0.002 | BH4: 4.93206 | BI4: 5 | BJ4: 0.053532 | BK4: =INDEX($BH:$BH,MATCH(BI4,$BF:$BF,1)) -> 524.55035 | BL4: =BK4/50 -BM$2 -> 10.533214 | BN4: 2 | BO4: 0.1 | BP4: 0.00202 | BQ4: -29.31025 | BR4: 5 | BS4: 0.05072 | BT4: =INDEX($BQ:$BQ,MATCH(BR4,$BO:$BO,1)) -> 491.84949 | BU4: =BT4/50 -BV$2 -> 10.555036 | BW4: 2 | BX4: 0.1 | BY4: 0.00161 | BZ4: 1.20039 | CA4: 5 | CB4: 0.046213 | CC4: =INDEX($BZ:$BZ,MATCH(CA4,$BX:$BX,1)) -> 533.97742 | CD4: =CC4/50 -CE$2 -> 10.713242 | CF4: 2 | CG4: 0.1 | CH4: 0.00187 | CI4: 5.05683 | CJ4: 5 | CK4: 0.054801 | CL4: =INDEX($CI:$CI,MATCH(CJ4,$CG:$CG,1)) -> 542.23022 | CM4: =CL4/50 -CN$2 -> 10.875542 | CP4: 2 | CQ4: 0.1 | CR4: 0.00192 | CS4: -32.08053 | CT4: 5 | CU4: 0.067038 | CV4: =INDEX($CS:$CS,MATCH(CT4,$CQ:$CQ,1)) -> 486.3718 | CW4: =CV4/50 -CX$2 -> 10.511673 | CY4: 2 | CZ4: 0.1 | DA4: 0.00149 | DB4: 0.70403 | DC4: 5 | DD4: 0.056826 | DE4: =INDEX($DB:$DB,MATCH(DC4,$CZ:$CZ,1)) -> 526.01855 | DF4: =DE4/50 -DG$2 -> 10.559502 | DH4: 2 | DI4: 0.1 | DJ4: 0.00192 | DK4: 3.10613 | DL4: 5 | DM4: 0.037047 | DN4: =INDEX($DK:$DK,MATCH(DL4,$DI:$DI,1)) -> 532.42346 | DO4: =DN4/50 -DP$2 -> 10.711018 | DQ4: 2 | DR4: 0.1 | DS4: 0.00179 | DT4: 3.00785 | DU4: 5 | DV4: 0.052265 | DW4: =INDEX($DT:$DT,MATCH(DU4,$DR:$DR,1)) -> 542.55212 | DX4: =DW4/50 -DY$2 -> 10.901089 | DZ4: 2 | EA4: 0.1 | EB4: 0.00193 | EC4: 3.55655 | ED4: 5 | EE4: 0.045985 | EF4: =INDEX($DT:$DT,MATCH(ED4,$DR:$DR,1)) -> 542.55212 | EG4: =EF4/50 -EH$2 -> 10.901089
B5: 3 | C5: 0.2 | D5: 0.00593 | E5: 22.32926 | F5: 10 | G5: 0.121314 | H5: =INDEX($E:$E,MATCH(F5,$C:$C,1)) -> 1059.0024 | I5: =H5/50 -J$2 -> 21.178946 | K5: 3 | L5: 0.2 | M5: 0.00596 | N5: 24.40177 | O5: 10 | P5: 0.115723 | Q5: =INDEX($N:$N,MATCH(O5,$L:$L,1)) -> 1006.2609 | R5: =Q5/50 -S$2 -> 20.128556 | T5: 3 | U5: 0.2 | V5: 0.00591 | W5: 10.89332 | X5: 10 | Y5: 0.133007 | Z5: =INDEX($W:$W,MATCH(X5,$U:$U,1)) -> 1001.3031 | AA5: =Z5/50 -AB$2 -> 20.263562 | AC5: 3 | AD5: 0.2 | AE5: 0.00597 | AF5: -5.39896 | AG5: 10 | AH5: 0.128603 | AI5: =INDEX($AF:$AF,MATCH(AG5,$AD:$AD,1)) -> 957.34039 | AJ5: =AI5/50 -AK$2 -> 19.754294 | AL5: 3 | AM5: 0.2 | AN5: 0.00601 | AO5: 21.28375 | AP5: 10 | AQ5: 0.120533 | AR5: =INDEX($AO:$AO,MATCH(AP5,$AM:$AM,1)) -> 968.50323 | AS5: =AR5/50 -AT$2 -> 19.390253 | AV5: 3 | AW5: 0.2 | AX5: 0.00602 | AY5: 24.21618 | AZ5: 10 | BA5: 0.122523 | BB5: =INDEX($AY:$AY,MATCH(AZ5,$AW:$AW,1)) -> 995.92761 | BC5: =BB5/50 -BD$2 -> 19.922987 | BE5: 3 | BF5: 0.2 | BG5: 0.00594 | BH5: 22.53367 | BI5: 10 | BJ5: 0.105703 | BK5: =INDEX($BH:$BH,MATCH(BI5,$BF:$BF,1)) -> 961.46552 | BL5: =BK5/50 -BM$2 -> 19.271517 | BN5: 3 | BO5: 0.2 | BP5: 0.00592 | BQ5: -10.93125 | BR5: 10 | BS5: 0.09764 | BT5: =INDEX($BQ:$BQ,MATCH(BR5,$BO:$BO,1)) -> 931.63373 | BU5: =BT5/50 -BV$2 -> 19.350721 | BW5: 3 | BX5: 0.2 | BY5: 0.0059 | BZ5: 20.39887 | CA5: 10 | CB5: 0.100864 | CC5: =INDEX($BZ:$BZ,MATCH(CA5,$BX:$BX,1)) -> 957.91742 | CD5: =CC5/50 -CE$2 -> 19.192042 | CF5: 3 | CG5: 0.2 | CH5: 0.00594 | CI5: 24.34181 | CJ5: 10 | CK5: 0.112987 | CL5: =INDEX($CI:$CI,MATCH(CJ5,$CG:$CG,1)) -> 987.4491 | CM5: =CL5/50 -CN$2 -> 19.779919 | CP5: 3 | CQ5: 0.2 | CR5: 0.00592 | CS5: -13.62982 | CT5: 10 | CU5: 0.116044 | CV5: =INDEX($CS:$CS,MATCH(CT5,$CQ:$CQ,1)) -> 907.47388 | CW5: =CV5/50 -CX$2 -> 18.933715 | CY5: 3 | CZ5: 0.2 | DA5: 0.00593 | DB5: 20.25216 | DC5: 10 | DD5: 0.10585 | DE5: =INDEX($DB:$DB,MATCH(DC5,$CZ:$CZ,1)) -> 948.68994 | DF5: =DE5/50 -DG$2 -> 19.01293 | DH5: 3 | DI5: 0.2 | DJ5: 0.00592 | DK5: 20.03774 | DL5: 10 | DM5: 0.092755 | DN5: =INDEX($DK:$DK,MATCH(DL5,$DI:$DI,1)) -> 951.74982 | DO5: =DN5/50 -DP$2 -> 19.097545 | DQ5: 3 | DR5: 0.2 | DS5: 0.00594 | DT5: 21.89614 | DU5: 10 | DV5: 0.100096 | DW5: =INDEX($DT:$DT,MATCH(DU5,$DR:$DR,1)) -> 962.43243 | DX5: =DW5/50 -DY$2 -> 19.298695 | DZ5: 3 | EA5: 0.2 | EB5: 0.00592 | EC5: 21.76481 | ED5: 10 | EE5: 0.099315 | EF5: =INDEX($DT:$DT,MATCH(ED5,$DR:$DR,1)) -> 962.43243 | EG5: =EF5/50 -EH$2 -> 19.298695
B6: 4 | C6: 0.3 | D6: 0.00925 | E6: 37.50064 | F6: 15 | G6: 0.170421 | H6: =INDEX($E:$E,MATCH(F6,$C:$C,1)) -> 1386.5933 | I6: =H6/50 -J$2 -> 27.730763 | K6: 4 | L6: 0.3 | M6: 0.00922 | N6: 39.02543 | O6: 15 | P6: 0.167395 | Q6: =INDEX($N:$N,MATCH(O6,$L:$L,1)) -> 1395.3009 | R6: =Q6/50 -S$2 -> 27.909357 | T6: 4 | U6: 0.3 | V6: 0.00925 | W6: 26.09324 | X6: 15 | Y6: 0.180618 | Z6: =INDEX($W:$W,MATCH(X6,$U:$U,1)) -> 1400.386 | AA6: =Z6/50 -AB$2 -> 28.24522 | AC6: 4 | AD6: 0.3 | AE6: 0.00928 | AF6: 9.59118 | AG6: 15 | AH6: 0.174061 | AI6: =INDEX($AF:$AF,MATCH(AG6,$AD:$AD,1)) -> 1351.071 | AJ6: =AI6/50 -AK$2 -> 27.628907 | AL6: 4 | AM6: 0.3 | AN6: 0.00922 | AO6: 34.98667 | AP6: 15 | AQ6: 0.17253 | AR6: =INDEX($AO:$AO,MATCH(AP6,$AM:$AM,1)) -> 1361.8131 | AS6: =AR6/50 -AT$2 -> 27.256451 | AV6: 4 | AW6: 0.3 | AX6: 0.00926 | AY6: 38.67142 | AZ6: 15 | BA6: 0.17742 | BB6: =INDEX($AY:$AY,MATCH(AZ6,$AW:$AW,1)) -> 1373.9419 | BC6: =BB6/50 -BD$2 -> 27.483273 | BE6: 4 | BF6: 0.3 | BG6: 0.00926 | BH6: 37.20214 | BI6: 15 | BJ6: 0.150838 | BK6: =INDEX($BH:$BH,MATCH(BI6,$BF:$BF,1)) -> 1343.2742 | BL6: =BK6/50 -BM$2 -> 26.90769 | BN6: 4 | BO6: 0.3 | BP6: 0.00923 | BQ6: 3.90801 | BR6: 15 | BS6: 0.141127 | BT6: =INDEX($BQ:$BQ,MATCH(BR6,$BO:$BO,1)) -> 1314.2837 | BU6: =BT6/50 -BV$2 -> 27.00372 | BW6: 4 | BX6: 0.3 | BY6: 0.00922 | BZ6: 34.93936 | CA6: 15 | CB6: 0.147049 | CC6: =INDEX($BZ:$BZ,MATCH(CA6,$BX:$BX,1)) -> 1341.4857 | CD6: =CC6/50 -CE$2 -> 26.863408 | CF6: 4 | CG6: 0.3 | CH6: 0.00927 | CI6: 39.45032 | CJ6: 15 | CK6: 0.156911 | CL6: =INDEX($CI:$CI,MATCH(CJ6,$CG:$CG,1)) -> 1369.8976 | CM6: =CL6/50 -CN$2 -> 27.428889 | CP6: 4 | CQ6: 0.3 | CR6: 0.00925 | CS6: 0.97494 | CT6: 15 | CU6: 0.166112 | CV6: =INDEX($CS:$CS,MATCH(CT6,$CQ:$CQ,1)) -> 1284.7294 | CW6: =CV6/50 -CX$2 -> 26.478825 | CY6: 4 | CZ6: 0.3 | DA6: 0.00923 | DB6: 35.21073 | DC6: 15 | DD6: 0.158727 | DE6: =INDEX($DB:$DB,MATCH(DC6,$CZ:$CZ,1)) -> 1333.5302 | DF6: =DE6/50 -DG$2 -> 26.709734 | DH6: 4 | DI6: 0.3 | DJ6: 0.00924 | DK6: 34.82971 | DL6: 15 | DM6: 0.140189 | DN6: =INDEX($DK:$DK,MATCH(DL6,$DI:$DI,1)) -> 1342.5884 | DO6: =DN6/50 -DP$2 -> 26.914316 | DQ6: 4 | DR6: 0.3 | DS6: 0.00924 | DT6: 37.19354 | DU6: 15 | DV6: 0.149917 | DW6: =INDEX($DT:$DT,MATCH(DU6,$DR:$DR,1)) -> 1348.9824 | DX6: =DW6/50 -DY$2 -> 27.029695 | DZ6: 4 | EA6: 0.3 | EB6: 0.00924 | EC6: 36.24033 | ED6: 15 | EE6: 0.143988 | EF6: =INDEX($DT:$DT,MATCH(ED6,$DR:$DR,1)) -> 1348.9824 | EG6: =EF6/50 -EH$2 -> 27.029695
B7: 5 | C7: 0.4 | D7: 0.01259 | E7: 52.31504 | F7: 20 | G7: 0.201564 | H7: =INDEX($E:$E,MATCH(F7,$C:$C,1)) -> 1670.7198 | I7: =H7/50 -J$2 -> 33.413294 | K7: 5 | L7: 0.4 | M7: 0.01257 | N7: 54.42719 | O7: 20 | P7: 0.210055 | Q7: =INDEX($N:$N,MATCH(O7,$L:$L,1)) -> 1714.9608 | R7: =Q7/50 -S$2 -> 34.302555 | T7: 5 | U7: 0.4 | V7: 0.01259 | W7: 41.31741 | X7: 20 | Y7: 0.220183 | Z7: =INDEX($W:$W,MATCH(X7,$U:$U,1)) -> 1723.8905 | AA7: =Z7/50 -AB$2 -> 34.71531 | AC7: 5 | AD7: 0.4 | AE7: 0.0126 | AF7: 23.98091 | AG7: 20 | AH7: 0.206849 | AI7: =INDEX($AF:$AF,MATCH(AG7,$AD:$AD,1)) -> 1644.0842 | AJ7: =AI7/50 -AK$2 -> 33.489171 | AL7: 5 | AM7: 0.4 | AN7: 0.01261 | AO7: 50.07394 | AP7: 20 | AQ7: 0.204142 | AR7: =INDEX($AO:$AO,MATCH(AP7,$AM:$AM,1)) -> 1632.3374 | AS7: =AR7/50 -AT$2 -> 32.666937 | AV7: 5 | AW7: 0.4 | AX7: 0.0126 | AY7: 53.57573 | AZ7: 20 | BA7: 0.209853 | BB7: =INDEX($AY:$AY,MATCH(AZ7,$AW:$AW,1)) -> 1635.1219 | BC7: =BB7/50 -BD$2 -> 32.706874 | BE7: 5 | BF7: 0.4 | BG7: 0.01257 | BH7: 50.98991 | BI7: 20 | BJ7: 0.189059 | BK7: =INDEX($BH:$BH,MATCH(BI7,$BF:$BF,1)) -> 1682.9093 | BL7: =BK7/50 -BM$2 -> 33.700393 | BN7: 5 | BO7: 0.4 | BP7: 0.0126 | BQ7: 18.8865 | BR7: 20 | BS7: 0.191722 | BT7: =INDEX($BQ:$BQ,MATCH(BR7,$BO:$BO,1)) -> 1636.7775 | BU7: =BT7/50 -BV$2 -> 33.453596 | BW7: 5 | BX7: 0.4 | BY7: 0.01257 | BZ7: 49.58845 | CA7: 20 | CB7: 0.186041 | CC7: =INDEX($BZ:$BZ,MATCH(CA7,$BX:$BX,1)) -> 1660.3229 | CD7: =CC7/50 -CE$2 -> 33.240152 | CF7: 5 | CG7: 0.4 | CH7: 0.01259 | CI7: 53.92929 | CJ7: 20 | CK7: 0.190897 | CL7: =INDEX($CI:$CI,MATCH(CJ7,$CG:$CG,1)) -> 1645.8389 | CM7: =CL7/50 -CN$2 -> 32.947715 | CP7: 5 | CQ7: 0.4 | CR7: 0.01258 | CS7: 14.95837 | CT7: 20 | CU7: 0.209299 | CV7: =INDEX($CS:$CS,MATCH(CT7,$CQ:$CQ,1)) -> 1530.7856 | CW7: =CV7/50 -CX$2 -> 31.39995 | CY7: 5 | CZ7: 0.4 | DA7: 0.01256 | DB7: 49.81997 | DC7: 20 | DD7: 0.190119 | DE7: =INDEX($DB:$DB,MATCH(DC7,$CZ:$CZ,1)) -> 1647.4077 | DF7: =DE7/50 -DG$2 -> 32.987285 | DH7: 5 | DI7: 0.4 | DJ7: 0.01257 | DK7: 47.69797 | DL7: 20 | DM7: 0.179601 | DN7: =INDEX($DK:$DK,MATCH(DL7,$DI:$DI,1)) -> 1676.359 | DO7: =DN7/50 -DP$2 -> 33.589729 | DQ7: 5 | DR7: 0.4 | DS7: 0.01257 | DT7: 51.00179 | DU7: 20 | DV7: 0.189372 | DW7: =INDEX($DT:$DT,MATCH(DU7,$DR:$DR,1)) -> 1670.2986 | DX7: =DW7/50 -DY$2 -> 33.456018 | DZ7: 5 | EA7: 0.4 | EB7: 0.01257 | EC7: 50.80299 | ED7: 20 | EE7: 0.18839 | EF7: =INDEX($DT:$DT,MATCH(ED7,$DR:$DR,1)) -> 1670.2986 | EG7: =EF7/50 -EH$2 -> 33.456018
B8: 6 | C8: 0.5 | D8: 0.01589 | E8: 67.13201 | F8: 25 | G8: 0.243053 | H8: =INDEX($E:$E,MATCH(F8,$C:$C,1)) -> 2023.2876 | I8: =H8/50 -J$2 -> 40.464649 | K8: 6 | L8: 0.5 | M8: 0.01591 | N8: 68.74162 | O8: 25 | P8: 0.257992 | Q8: =INDEX($N:$N,MATCH(O8,$L:$L,1)) -> 2092.4758 | R8: =Q8/50 -S$2 -> 41.852855 | T8: 6 | U8: 0.5 | V8: 0.01593 | W8: 56.31699 | X8: 25 | Y8: 0.264557 | Z8: =INDEX($W:$W,MATCH(X8,$U:$U,1)) -> 2085.6067 | AA8: =Z8/50 -AB$2 -> 41.949634 | AC8: 6 | AD8: 0.5 | AE8: 0.01591 | AF8: 38.62905 | AG8: 25 | AH8: 0.26077 | AI8: =INDEX($AF:$AF,MATCH(AG8,$AD:$AD,1)) -> 2011.6736 | AJ8: =AI8/50 -AK$2 -> 40.840958 | AL8: 6 | AM8: 0.5 | AN8: 0.01591 | AO8: 64.80479 | AP8: 25 | AQ8: 0.260686 | AR8: =INDEX($AO:$AO,MATCH(AP8,$AM:$AM,1)) -> 2053.678 | AS8: =AR8/50 -AT$2 -> 41.093748 | AV8: 6 | AW8: 0.5 | AX8: 0.01593 | AY8: 67.90805 | AZ8: 25 | BA8: 0.249334 | BB8: =INDEX($AY:$AY,MATCH(AZ8,$AW:$AW,1)) -> 1982.7106 | BC8: =BB8/50 -BD$2 -> 39.658647 | BE8: 6 | BF8: 0.5 | BG8: 0.01588 | BH8: 65.50594 | BI8: 25 | BJ8: 0.233073 | BK8: =INDEX($BH:$BH,MATCH(BI8,$BF:$BF,1)) -> 2029.0569 | BL8: =BK8/50 -BM$2 -> 40.623344 | BN8: 6 | BO8: 0.5 | BP8: 0.01591 | BQ8: 32.61319 | BR8: 25 | BS8: 0.233855 | BT8: =INDEX($BQ:$BQ,MATCH(BR8,$BO:$BO,1)) -> 2029.2065 | BU8: =BT8/50 -BV$2 -> 41.302177 | BW8: 6 | BX8: 0.5 | BY8: 0.01593 | BZ8: 63.95025 | CA8: 25 | CB8: 0.228488 | CC8: =INDEX($BZ:$BZ,MATCH(CA8,$BX:$BX,1)) -> 2058.4766 | CD8: =CC8/50 -CE$2 -> 41.203225 | CF8: 6 | CG8: 0.5 | CH8: 0.01593 | CI8: 68.62737 | CJ8: 25 | CK8: 0.246357 | CL8: =INDEX($CI:$CI,MATCH(CJ8,$CG:$CG,1)) -> 2065.8975 | CM8: =CL8/50 -CN$2 -> 41.348887 | CP8: 6 | CQ8: 0.5 | CR8: 0.01592 | CS8: 29.30192 | CT8: 25 | CU8: 0.250161 | CV8: =INDEX($CS:$CS,MATCH(CT8,$CQ:$CQ,1)) -> 1882.5316 | CW8: =CV8/50 -CX$2 -> 38.43487 | CY8: 6 | CZ8: 0.5 | DA8: 0.01588 | DB8: 64.02524 | DC8: 25 | DD8: 0.246172 | DE8: =INDEX($DB:$DB,MATCH(DC8,$CZ:$CZ,1)) -> 2040.5783 | DF8: =DE8/50 -DG$2 -> 40.850696 | DH8: 6 | DI8: 0.5 | DJ8: 0.01591 | DK8: 61.92271 | DL8: 25 | DM8: 0.2288 | DN8: =INDEX($DK:$DK,MATCH(DL8,$DI:$DI,1)) -> 2079.2898 | DO8: =DN8/50 -DP$2 -> 41.648344 | DQ8: 6 | DR8: 0.5 | DS8: 0.0159 | DT8: 65.46822 | DU8: 25 | DV8: 0.236913 | DW8: =INDEX($DT:$DT,MATCH(DU8,$DR:$DR,1)) -> 2075.8254 | DX8: =DW8/50 -DY$2 -> 41.566555 | DZ8: 6 | EA8: 0.5 | EB8: 0.01591 | EC8: 64.90306 | ED8: 25 | EE8: 0.2391 | EF8: =INDEX($DT:$DT,MATCH(ED8,$DR:$DR,1)) -> 2075.8254 | EG8: =EF8/50 -EH$2 -> 41.566555
B9: 7 | C9: 0.6 | D9: 0.01924 | E9: 82.60587 | F9: 30 | G9: 0.305862 | H9: =INDEX($E:$E,MATCH(F9,$C:$C,1)) -> 2407.396 | I9: =H9/50 -J$2 -> 48.146817 | K9: 7 | L9: 0.6 | M9: 0.01923 | N9: 83.32127 | O9: 30 | P9: 0.293562 | Q9: =INDEX($N:$N,MATCH(O9,$L:$L,1)) -> 2460.7634 | R9: =Q9/50 -S$2 -> 49.218607 | T9: 7 | U9: 0.6 | V9: 0.01928 | W9: 70.97006 | X9: 30 | Y9: 0.332109 | Z9: =INDEX($W:$W,MATCH(X9,$U:$U,1)) -> 2494.9145 | AA9: =Z9/50 -AB$2 -> 50.135791 | AC9: 7 | AD9: 0.6 | AE9: 0.01925 | AF9: 53.39552 | AG9: 30 | AH9: 0.300926 | AI9: =INDEX($AF:$AF,MATCH(AG9,$AD:$AD,1)) -> 2451.5134 | AJ9: =AI9/50 -AK$2 -> 49.637755 | AL9: 7 | AM9: 0.6 | AN9: 0.0192 | AO9: 77.74777 | AP9: 30 | AQ9: 0.304251 | AR9: =INDEX($AO:$AO,MATCH(AP9,$AM:$AM,1)) -> 2468.7847 | AS9: =AR9/50 -AT$2 -> 49.395882 | AV9: 7 | AW9: 0.6 | AX9: 0.01925 | AY9: 82.09801 | AZ9: 30 | BA9: 0.290903 | BB9: =INDEX($AY:$AY,MATCH(AZ9,$AW:$AW,1)) -> 2321.0781 | BC9: =BB9/50 -BD$2 -> 46.425998 | BE9: 7 | BF9: 0.6 | BG9: 0.01929 | BH9: 79.60471 | BI9: 30 | BJ9: 0.28547 | BK9: =INDEX($BH:$BH,MATCH(BI9,$BF:$BF,1)) -> 2418.6362 | BL9: =BK9/50 -BM$2 -> 48.414931 | BN9: 7 | BO9: 0.6 | BP9: 0.01925 | BQ9: 46.70567 | BR9: 30 | BS9: 0.288172 | BT9: =INDEX($BQ:$BQ,MATCH(BR9,$BO:$BO,1)) -> 2444.3733 | BU9: =BT9/50 -BV$2 -> 49.605512 | BW9: 7 | BX9: 0.6 | BY9: 0.01927 | BZ9: 77.61271 | CA9: 30 | CB9: 0.279822 | CC9: =INDEX($BZ:$BZ,MATCH(CA9,$BX:$BX,1)) -> 2461.4541 | CD9: =CC9/50 -CE$2 -> 49.262776 | CF9: 7 | CG9: 0.6 | CH9: 0.01929 | CI9: 83.55175 | CJ9: 30 | CK9: 0.292215 | CL9: =INDEX($CI:$CI,MATCH(CJ9,$CG:$CG,1)) -> 2477.7402 | CM9: =CL9/50 -CN$2 -> 49.585742 | CP9: 7 | CQ9: 0.6 | CR9: 0.01929 | CS9: 43.10009 | CT9: 30 | CU9: 0.301387 | CV9: =INDEX($CS:$CS,MATCH(CT9,$CQ:$CQ,1)) -> 2304.3398 | CW9: =CV9/50 -CX$2 -> 46.871034 | CY9: 7 | CZ9: 0.6 | DA9: 0.01925 | DB9: 78.21851 | DC9: 30 | DD9: 0.297215 | DE9: =INDEX($DB:$DB,MATCH(DC9,$CZ:$CZ,1)) -> 2448.7231 | DF9: =DE9/50 -DG$2 -> 49.013594 | DH9: 7 | DI9: 0.6 | DJ9: 0.01929 | DK9: 75.60043 | DL9: 30 | DM9: 0.278409 | DN9: =INDEX($DK:$DK,MATCH(DL9,$DI:$DI,1)) -> 2498.3125 | DO9: =DN9/50 -DP$2 -> 50.028799 | DQ9: 7 | DR9: 0.6 | DS9: 0.01925 | DT9: 79.52792 | DU9: 30 | DV9: 0.285029 | DW9: =INDEX($DT:$DT,MATCH(DU9,$DR:$DR,1)) -> 2496.7051 | DX9: =DW9/50 -DY$2 -> 49.984148 | DZ9: 7 | EA9: 0.6 | EB9: 0.01929 | EC9: 79.28552 | ED9: 30 | EE9: 0.284974 | EF9: =INDEX($DT:$DT,MATCH(ED9,$DR:$DR,1)) -> 2496.7051 | EG9: =EF9/50 -EH$2 -> 49.984148
B10: 8 | C10: 0.7 | D10: 0.0226 | E10: 96.33035 | F10: 35 | G10: 0.34572 | H10: =INDEX($E:$E,MATCH(F10,$C:$C,1)) -> 2836.7395 | I10: =H10/50 -J$2 -> 56.733687 | K10: 8 | L10: 0.7 | M10: 0.0226 | N10: 97.41126 | O10: 35 | P10: 0.351775 | Q10: =INDEX($N:$N,MATCH(O10,$L:$L,1)) -> 2860.2759 | R10: =Q10/50 -S$2 -> 57.208856 | T10: 8 | U10: 0.7 | V10: 0.02259 | W10: 85.21185 | X10: 35 | Y10: 0.376781 | Z10: =INDEX($W:$W,MATCH(X10,$U:$U,1)) -> 2934.6655 | AA10: =Z10/50 -AB$2 -> 58.930811 | AC10: 8 | AD10: 0.7 | AE10: 0.02253 | AF10: 67.01286 | AG10: 35 | AH10: 0.356968 | AI10: =INDEX($AF:$AF,MATCH(AG10,$AD:$AD,1)) -> 2883.3662 | AJ10: =AI10/50 -AK$2 -> 58.274811 | AL10: 8 | AM10: 0.7 | AN10: 0.0226 | AO10: 92.57961 | AP10: 35 | AQ10: 0.355651 | AR10: =INDEX($AO:$AO,MATCH(AP10,$AM:$AM,1)) -> 2881.5185 | AS10: =AR10/50 -AT$2 -> 57.65056 | AV10: 8 | AW10: 0.7 | AX10: 0.02259 | AY10: 96.23087 | AZ10: 35 | BA10: 0.329648 | BB10: =INDEX($AY:$AY,MATCH(AZ10,$AW:$AW,1)) -> 2750.9749 | BC10: =BB10/50 -BD$2 -> 55.023932 | BE10: 8 | BF10: 0.7 | BG10: 0.0226 | BH10: 93.79571 | BI10: 35 | BJ10: 0.336537 | BK10: =INDEX($BH:$BH,MATCH(BI10,$BF:$BF,1)) -> 2834.6885 | BL10: =BK10/50 -BM$2 -> 56.735976 | BN10: 8 | BO10: 0.7 | BP10: 0.02263 | BQ10: 61.13026 | BR10: 35 | BS10: 0.344358 | BT10: =INDEX($BQ:$BQ,MATCH(BR10,$BO:$BO,1)) -> 2862.1824 | BU10: =BT10/50 -BV$2 -> 57.961694 | BW10: 8 | BX10: 0.7 | BY10: 0.02261 | BZ10: 91.5381 | CA10: 35 | CB10: 0.333386 | CC10: =INDEX($BZ:$BZ,MATCH(CA10,$BX:$BX,1)) -> 2860.1597 | CD10: =CC10/50 -CE$2 -> 57.236887 | CF10: 8 | CG10: 0.7 | CH10: 0.02258 | CI10: 97.45599 | CJ10: 35 | CK10: 0.348075 | CL10: =INDEX($CI:$CI,MATCH(CJ10,$CG:$CG,1)) -> 2890.3144 | CM10: =CL10/50 -CN$2 -> 57.837226 | CP10: 8 | CQ10: 0.7 | CR10: 0.02261 | CS10: 55.81335 | CT10: 35 | CU10: 0.343041 | CV10: =INDEX($CS:$CS,MATCH(CT10,$CQ:$CQ,1)) -> 2715.8352 | CW10: =CV10/50 -CX$2 -> 55.100942 | CY10: 8 | CZ10: 0.7 | DA10: 0.02261 | DB10: 91.31828 | DC10: 35 | DD10: 0.345849 | DE10: =INDEX($DB:$DB,MATCH(DC10,$CZ:$CZ,1)) -> 2863.5671 | DF10: =DE10/50 -DG$2 -> 57.310474 | DH10: 8 | DI10: 0.7 | DJ10: 0.02261 | DK10: 88.44064 | DL10: 35 | DM10: 0.331275 | DN10: =INDEX($DK:$DK,MATCH(DL10,$DI:$DI,1)) -> 2915.9092 | DO10: =DN10/50 -DP$2 -> 58.380732 | DQ10: 8 | DR10: 0.7 | DS10: 0.02262 | DT10: 92.72227 | DU10: 35 | DV10: 0.338231 | DW10: =INDEX($DT:$DT,MATCH(DU10,$DR:$DR,1)) -> 2911.7656 | DX10: =DW10/50 -DY$2 -> 58.285359 | DZ10: 8 | EA10: 0.7 | EB10: 0.02261 | EC10: 93.04475 | ED10: 35 | EE10: 0.338818 | EF10: =INDEX($DT:$DT,MATCH(ED10,$DR:$DR,1)) -> 2911.7656 | EG10: =EF10/50 -EH$2 -> 58.285359
B11: 9 | C11: 0.8 | D11: 0.02588 | E11: 110.76505 | F11: 40 | G11: 0.380336 | H11: =INDEX($E:$E,MATCH(F11,$C:$C,1)) -> 3271.3091 | I11: =H11/50 -J$2 -> 65.425079 | K11: 9 | L11: 0.8 | M11: 0.02592 | N11: 111.87691 | O11: 40 | P11: 0.392228 | Q11: =INDEX($N:$N,MATCH(O11,$L:$L,1)) -> 3295.906 | R11: =Q11/50 -S$2 -> 65.921459 | T11: 9 | U11: 0.8 | V11: 0.02587 | W11: 99.46307 | X11: 40 | Y11: 0.439563 | Z11: =INDEX($W:$W,MATCH(X11,$U:$U,1)) -> 3370.2019 | AA11: =Z11/50 -AB$2 -> 67.641538 | AC11: 9 | AD11: 0.8 | AE11: 0.02591 | AF11: 81.06045 | AG11: 40 | AH11: 0.408276 | AI11: =INDEX($AF:$AF,MATCH(AG11,$AD:$AD,1)) -> 3311.811 | AJ11: =AI11/50 -AK$2 -> 66.843707 | AL11: 9 | AM11: 0.8 | AN11: 0.02595 | AO11: 106.66486 | AP11: 40 | AQ11: 0.401567 | AR11: =INDEX($AO:$AO,MATCH(AP11,$AM:$AM,1)) -> 3301.9326 | AS11: =AR11/50 -AT$2 -> 66.058841 | AV11: 9 | AW11: 0.8 | AX11: 0.0259 | AY11: 110.42807 | AZ11: 40 | BA11: 0.388674 | BB11: =INDEX($AY:$AY,MATCH(AZ11,$AW:$AW,1)) -> 3185.0718 | BC11: =BB11/50 -BD$2 -> 63.705871 | BE11: 9 | BF11: 0.8 | BG11: 0.02591 | BH11: 106.44426 | BI11: 40 | BJ11: 0.388781 | BK11: =INDEX($BH:$BH,MATCH(BI11,$BF:$BF,1)) -> 3281.0847 | BL11: =BK11/50 -BM$2 -> 65.663901 | BN11: 9 | BO11: 0.8 | BP11: 0.02594 | BQ11: 74.53127 | BR11: 40 | BS11: 0.393226 | BT11: =INDEX($BQ:$BQ,MATCH(BR11,$BO:$BO,1)) -> 3308.4756 | BU11: =BT11/50 -BV$2 -> 66.887558 | BW11: 9 | BX11: 0.8 | BY11: 0.02593 | BZ11: 104.70209 | CA11: 40 | CB11: 0.385216 | CC11: =INDEX($BZ:$BZ,MATCH(CA11,$BX:$BX,1)) -> 3293.9358 | CD11: =CC11/50 -CE$2 -> 65.91241 | CF11: 9 | CG11: 0.8 | CH11: 0.02594 | CI11: 111.28018 | CJ11: 40 | CK11: 0.402776 | CL11: =INDEX($CI:$CI,MATCH(CJ11,$CG:$CG,1)) -> 3334.8445 | CM11: =CL11/50 -CN$2 -> 66.727827 | CP11: 9 | CQ11: 0.8 | CR11: 0.02594 | CS11: 69.11845 | CT11: 40 | CU11: 0.393244 | CV11: =INDEX($CS:$CS,MATCH(CT11,$CQ:$CQ,1)) -> 3158.772 | CW11: =CV11/50 -CX$2 -> 63.959677 | CY11: 9 | CZ11: 0.8 | DA11: 0.02593 | DB11: 105.28852 | DC11: 40 | DD11: 0.395846 | DE11: =INDEX($DB:$DB,MATCH(DC11,$CZ:$CZ,1)) -> 3302.1008 | DF11: =DE11/50 -DG$2 -> 66.081148 | DH11: 9 | DI11: 0.8 | DJ11: 0.02593 | DK11: 102.48106 | DL11: 40 | DM11: 0.384866 | DN11: =INDEX($DK:$DK,MATCH(DL11,$DI:$DI,1)) -> 3362.7183 | DO11: =DN11/50 -DP$2 -> 67.316914 | DQ11: 9 | DR11: 0.8 | DS11: 0.02594 | DT11: 105.96255 | DU11: 40 | DV11: 0.39227 | DW11: =INDEX($DT:$DT,MATCH(DU11,$DR:$DR,1)) -> 3334.0391 | DX11: =DW11/50 -DY$2 -> 66.730827 | DZ11: 9 | EA11: 0.8 | EB11: 0.02593 | EC11: 106.27454 | ED11: 40 | EE11: 0.395958 | EF11: =INDEX($DT:$DT,MATCH(ED11,$DR:$DR,1)) -> 3334.0391 | EG11: =EF11/50 -EH$2 -> 66.730827
B12: 10 | C12: 0.9 | D12: 0.02926 | E12: 125.08131 | F12: 45 | G12: 0.44483 | H12: =INDEX($E:$E,MATCH(F12,$C:$C,1)) -> 3717.3472 | I12: =H12/50 -J$2 -> 74.345841 | K12: 10 | L12: 0.9 | M12: 0.02926 | N12: 126.16825 | O12: 45 | P12: 0.452001 | Q12: =INDEX($N:$N,MATCH(O12,$L:$L,1)) -> 3757.0046 | R12: =Q12/50 -S$2 -> 75.143432 | T12: 10 | U12: 0.9 | V12: 0.02923 | W12: 113.29327 | X12: 45 | Y12: 0.479861 | Z12: =INDEX($W:$W,MATCH(X12,$U:$U,1)) -> 3829.3103 | AA12: =Z12/50 -AB$2 -> 76.823706 | AC12: 10 | AD12: 0.9 | AE12: 0.02927 | AF12: 95.44229 | AG12: 45 | AH12: 0.461008 | AI12: =INDEX($AF:$AF,MATCH(AG12,$AD:$AD,1)) -> 3744.5276 | AJ12: =AI12/50 -AK$2 -> 75.498038 | AL12: 10 | AM12: 0.9 | AN12: 0.02924 | AO12: 119.69788 | AP12: 45 | AQ12: 0.456572 | AR12: =INDEX($AO:$AO,MATCH(AP12,$AM:$AM,1)) -> 3758.0415 | AS12: =AR12/50 -AT$2 -> 75.181019 | AV12: 10 | AW12: 0.9 | AX12: 0.02923 | AY12: 123.88917 | AZ12: 45 | BA12: 0.446476 | BB12: =INDEX($AY:$AY,MATCH(AZ12,$AW:$AW,1)) -> 3626.4868 | BC12: =BB12/50 -BD$2 -> 72.534172 | BE12: 10 | BF12: 0.9 | BG12: 0.02926 | BH12: 119.51877 | BI12: 45 | BJ12: 0.442596 | BK12: =INDEX($BH:$BH,MATCH(BI12,$BF:$BF,1)) -> 3731.2014 | BL12: =BK12/50 -BM$2 -> 74.666235 | BN12: 10 | BO12: 0.9 | BP12: 0.02919 | BQ12: 87.38879 | BR12: 45 | BS12: 0.450596 | BT12: =INDEX($BQ:$BQ,MATCH(BR12,$BO:$BO,1)) -> 3761.3977 | BU12: =BT12/50 -BV$2 -> 75.946001 | BW12: 10 | BX12: 0.9 | BY12: 0.02927 | BZ12: 117.35431 | CA12: 45 | CB12: 0.434467 | CC12: =INDEX($BZ:$BZ,MATCH(CA12,$BX:$BX,1)) -> 3742.4492 | CD12: =CC12/50 -CE$2 -> 74.882678 | CF12: 10 | CG12: 0.9 | CH12: 0.02924 | CI12: 124.77747 | CJ12: 45 | CK12: 0.452451 | CL12: =INDEX($CI:$CI,MATCH(CJ12,$CG:$CG,1)) -> 3786.9116 | CM12: =CL12/50 -CN$2 -> 75.76917 | CP12: 10 | CQ12: 0.9 | CR12: 0.02926 | CS12: 81.4973 | CT12: 45 | CU12: 0.462585 | CV12: =INDEX($CS:$CS,MATCH(CT12,$CQ:$CQ,1)) -> 3606.728 | CW12: =CV12/50 -CX$2 -> 72.918798 | CY12: 10 | CZ12: 0.9 | DA12: 0.02927 | DB12: 117.66131 | DC12: 45 | DD12: 0.449824 | DE12: =INDEX($DB:$DB,MATCH(DC12,$CZ:$CZ,1)) -> 3745.7034 | DF12: =DE12/50 -DG$2 -> 74.953199 | DH12: 10 | DI12: 0.9 | DJ12: 0.02926 | DK12: 114.9072 | DL12: 45 | DM12: 0.437397 | DN12: =INDEX($DK:$DK,MATCH(DL12,$DI:$DI,1)) -> 3819.4624 | DO12: =DN12/50 -DP$2 -> 76.451797 | DQ12: 10 | DR12: 0.9 | DS12: 0.02927 | DT12: 119.25312 | DU12: 45 | DV12: 0.445532 | DW12: =INDEX($DT:$DT,MATCH(DU12,$DR:$DR,1)) -> 3797.7629 | DX12: =DW12/50 -DY$2 -> 76.005305 | DZ12: 10 | EA12: 0.9 | EB12: 0.02925 | EC12: 118.60654 | ED12: 45 | EE12: 0.449242 | EF12: =INDEX($DT:$DT,MATCH(ED12,$DR:$DR,1)) -> 3797.7629 | EG12: =EF12/50 -EH$2 -> 76.005305
B13: 11 | C13: 1 | D13: 0.03262 | E13: 139.94548 | F13: 50 | G13: 0.508508 | H13: =INDEX($E:$E,MATCH(F13,$C:$C,1)) -> 4172.2583 | I13: =H13/50 -J$2 -> 83.444063 | K13: 11 | L13: 1 | M13: 0.03263 | N13: 140.09958 | O13: 50 | P13: 0.507178 | Q13: =INDEX($N:$N,MATCH(O13,$L:$L,1)) -> 4225.0728 | R13: =Q13/50 -S$2 -> 84.504794 | T13: 11 | U13: 1 | V13: 0.03254 | W13: 127.47369 | X13: 50 | Y13: 0.540776 | Z13: =INDEX($W:$W,MATCH(X13,$U:$U,1)) -> 4307.3315 | AA13: =Z13/50 -AB$2 -> 86.384131 | AC13: 11 | AD13: 1 | AE13: 0.03258 | AF13: 108.74468 | AG13: 50 | AH13: 0.511798 | AI13: =INDEX($AF:$AF,MATCH(AG13,$AD:$AD,1)) -> 4217.9087 | AJ13: =AI13/50 -AK$2 -> 84.96566 | AL13: 11 | AM13: 1 | AN13: 0.03262 | AO13: 132.74953 | AP13: 50 | AQ13: 0.519153 | AR13: =INDEX($AO:$AO,MATCH(AP13,$AM:$AM,1)) -> 4219.5698 | AS13: =AR13/50 -AT$2 -> 84.411585 | AV13: 11 | AW13: 1 | AX13: 0.0326 | AY13: 138.02049 | AZ13: 50 | BA13: 0.498199 | BB13: =INDEX($AY:$AY,MATCH(AZ13,$AW:$AW,1)) -> 4077.6804 | BC13: =BB13/50 -BD$2 -> 81.558044 | BE13: 11 | BF13: 1 | BG13: 0.0326 | BH13: 132.49783 | BI13: 50 | BJ13: 0.497804 | BK13: =INDEX($BH:$BH,MATCH(BI13,$BF:$BF,1)) -> 4189.2563 | BL13: =BK13/50 -BM$2 -> 83.827334 | BN13: 11 | BO13: 1 | BP13: 0.03257 | BQ13: 100.60294 | BR13: 50 | BS13: 0.505604 | BT13: =INDEX($BQ:$BQ,MATCH(BR13,$BO:$BO,1)) -> 4221.3955 | BU13: =BT13/50 -BV$2 -> 85.145957 | BW13: 11 | BX13: 1 | BY13: 0.0326 | BZ13: 129.99245 | CA13: 50 | CB13: 0.493261 | CC13: =INDEX($BZ:$BZ,MATCH(CA13,$BX:$BX,1)) -> 4198.4307 | CD13: =CC13/50 -CE$2 -> 84.002307 | CF13: 11 | CG13: 1 | CH13: 0.03258 | CI13: 137.92412 | CJ13: 50 | CK13: 0.512227 | CL13: =INDEX($CI:$CI,MATCH(CJ13,$CG:$CG,1)) -> 4250.3921 | CM13: =CL13/50 -CN$2 -> 85.038779 | CP13: 11 | CQ13: 1 | CR13: 0.03257 | CS13: 92.71731 | CT13: 50 | CU13: 0.500419 | CV13: =INDEX($CS:$CS,MATCH(CT13,$CQ:$CQ,1)) -> 4064.3081 | CW13: =CV13/50 -CX$2 -> 82.0704 | CY13: 11 | CZ13: 1 | DA13: 0.03258 | DB13: 129.95599 | DC13: 50 | DD13: 0.508606 | DE13: =INDEX($DB:$DB,MATCH(DC13,$CZ:$CZ,1)) -> 4199.9004 | DF13: =DE13/50 -DG$2 -> 84.037139 | DH13: 11 | DI13: 1 | DJ13: 0.03256 | DK13: 126.89165 | DL13: 50 | DM13: 0.495315 | DN13: =INDEX($DK:$DK,MATCH(DL13,$DI:$DI,1)) -> 4285.4609 | DO13: =DN13/50 -DP$2 -> 85.771767 | DQ13: 11 | DR13: 1 | DS13: 0.03259 | DT13: 130.88585 | DU13: 50 | DV13: 0.503534 | DW13: =INDEX($DT:$DT,MATCH(DU13,$DR:$DR,1)) -> 4268.7871 | DX13: =DW13/50 -DY$2 -> 85.425788 | DZ13: 11 | EA13: 1 | EB13: 0.03257 | EC13: 131.12865 | ED13: 50 | EE13: 0.501624 | EF13: =INDEX($DT:$DT,MATCH(ED13,$DR:$DR,1)) -> 4268.7871 | EG13: =EF13/50 -EH$2 -> 85.425788
B14: 12 | C14: 1.1 | D14: 0.03592 | E14: 153.72855 | F14: 55 | G14: 0.557232 | H14: =INDEX($E:$E,MATCH(F14,$C:$C,1)) -> 4635.4175 | I14: =H14/50 -J$2 -> 92.707247 | K14: 12 | L14: 1.1 | M14: 0.03593 | N14: 153.38652 | O14: 55 | P14: 0.572441 | Q14: =INDEX($N:$N,MATCH(O14,$L:$L,1)) -> 4699.4956 | R14: =Q14/50 -S$2 -> 93.993251 | T14: 12 | U14: 1.1 | V14: 0.03592 | W14: 140.60976 | X14: 55 | Y14: 0.593243 | Z14: =INDEX($W:$W,MATCH(X14,$U:$U,1)) -> 4793.7124 | AA14: =Z14/50 -AB$2 -> 96.111748 | AC14: 12 | AD14: 1.1 | AE14: 0.03593 | AF14: 121.70372 | AG14: 55 | AH14: 0.573443 | AI14: =INDEX($AF:$AF,MATCH(AG14,$AD:$AD,1)) -> 4695.125 | AJ14: =AI14/50 -AK$2 -> 94.509987 | AL14: 12 | AM14: 1.1 | AN14: 0.03593 | AO14: 146.07446 | AP14: 55 | AQ14: 0.570547 | AR14: =INDEX($AO:$AO,MATCH(AP14,$AM:$AM,1)) -> 4689.8154 | AS14: =AR14/50 -AT$2 -> 93.816497 | AV14: 12 | AW14: 1.1 | AX14: 0.03593 | AY14: 151.30034 | AZ14: 55 | BA14: 0.554428 | BB14: =INDEX($AY:$AY,MATCH(AZ14,$AW:$AW,1)) -> 4534.8525 | BC14: =BB14/50 -BD$2 -> 90.701486 | BE14: 12 | BF14: 1.1 | BG14: 0.03587 | BH14: 143.58792 | BI14: 55 | BJ14: 0.547149 | BK14: =INDEX($BH:$BH,MATCH(BI14,$BF:$BF,1)) -> 4654.8262 | BL14: =BK14/50 -BM$2 -> 93.13873 | BN14: 12 | BO14: 1.1 | BP14: 0.0359 | BQ14: 112.87325 | BR14: 55 | BS14: 0.556324 | BT14: =INDEX($BQ:$BQ,MATCH(BR14,$BO:$BO,1)) -> 4688.2056 | BU14: =BT14/50 -BV$2 -> 94.482158 | BW14: 12 | BX14: 1.1 | BY14: 0.03591 | BZ14: 142.34113 | CA14: 55 | CB14: 0.545609 | CC14: =INDEX($BZ:$BZ,MATCH(CA14,$BX:$BX,1)) -> 4662.9849 | CD14: =CC14/50 -CE$2 -> 93.293391 | CF14: 12 | CG14: 1.1 | CH14: 0.03591 | CI14: 149.94064 | CJ14: 55 | CK14: 0.564412 | CL14: =INDEX($CI:$CI,MATCH(CJ14,$CG:$CG,1)) -> 4724.8794 | CM14: =CL14/50 -CN$2 -> 94.528525 | CP14: 12 | CQ14: 1.1 | CR14: 0.0359 | CS14: 104.29501 | CT14: 55 | CU14: 0.556029 | CV14: =INDEX($CS:$CS,MATCH(CT14,$CQ:$CQ,1)) -> 4527.0835 | CW14: =CV14/50 -CX$2 -> 91.325907 | CY14: 12 | CZ14: 1.1 | DA14: 0.03589 | DB14: 141.78853 | DC14: 55 | DD14: 0.555497 | DE14: =INDEX($DB:$DB,MATCH(DC14,$CZ:$CZ,1)) -> 4659.4033 | DF14: =DE14/50 -DG$2 -> 93.227198 | DH14: 12 | DI14: 1.1 | DJ14: 0.0359 | DK14: 139.05853 | DL14: 55 | DM14: 0.548867 | DN14: =INDEX($DK:$DK,MATCH(DL14,$DI:$DI,1)) -> 4756.9419 | DO14: =DN14/50 -DP$2 -> 95.201386 | DQ14: 12 | DR14: 1.1 | DS14: 0.0359 | DT14: 142.93422 | DU14: 55 | DV14: 0.55333 | DW14: =INDEX($DT:$DT,MATCH(DU14,$DR:$DR,1)) -> 4745.2017 | DX14: =DW14/50 -DY$2 -> 94.954079 | DZ14: 12 | EA14: 1.1 | EB14: 0.0359 | EC14: 143.2924 | ED14: 55 | EE14: 0.560174 | EF14: =INDEX($DT:$DT,MATCH(ED14,$DR:$DR,1)) -> 4745.2017 | EG14: =EF14/50 -EH$2 -> 94.954079
... B23: 21 | C23: 2 | D23: 0.06592 | E23: 265.38251 | F23: 100 | G23: 1.048359 | H23: =INDEX($E:$E,MATCH(F23,$C:$C,1)) -> 9154.2285 | I23: =H23/50 -J$2 -> 183.08347 | K23: 21 | L23: 2 | M23: 0.0659 | N23: 253.45027 | O23: 100 | P23: 1.070678 | Q23: =INDEX($N:$N,MATCH(O23,$L:$L,1)) -> 9280.7266 | R23: =Q23/50 -S$2 -> 185.61787 | T23: 21 | U23: 2 | V23: 0.06593 | W23: 242.14925 | X23: 100 | Y23: 1.10514 | Z23: =INDEX($W:$W,MATCH(X23,$U:$U,1)) -> 9438.1318 | AA23: =Z23/50 -AB$2 -> 189.00014 | AC23: 21 | AD23: 2 | AE23: 0.06594 | AF23: 220.92207 | AG23: 100 | AH23: 1.07256 | AI23: =INDEX($AF:$AF,MATCH(AG23,$AD:$AD,1)) -> 9261.4297 | AJ23: =AI23/50 -AK$2 -> 185.83608 | AL23: 21 | AM23: 2 | AN23: 0.06591 | AO23: 245.38513 | AP23: 100 | AQ23: 1.077979 | AR23: =INDEX($AO:$AO,MATCH(AP23,$AM:$AM,1)) -> 9211.3398 | AS23: =AR23/50 -AT$2 -> 184.24699 | AV23: 21 | AW23: 2 | AX23: 0.06595 | AY23: 251.60686 | AZ23: 100 | BA23: 1.060092 | BB23: =INDEX($AY:$AY,MATCH(AZ23,$AW:$AW,1)) -> 8983.542 | BC23: =BB23/50 -BD$2 -> 179.67527 | BE23: 21 | BF23: 2 | BG23: 0.06586 | BH23: 242.29008 | BI23: 100 | BJ23: 1.048894 | BK23: =INDEX($BH:$BH,MATCH(BI23,$BF:$BF,1)) -> 9142.7129 | BL23: =BK23/50 -BM$2 -> 182.89646 | BN23: 21 | BO23: 2 | BP23: 0.06592 | BQ23: 213.3779 | BR23: 100 | BS23: 1.054214 | BT23: =INDEX($BQ:$BQ,MATCH(BR23,$BO:$BO,1)) -> 9177.2324 | BU23: =BT23/50 -BV$2 -> 184.2627 | BW23: 21 | BX23: 2 | BY23: 0.06588 | BZ23: 237.80368 | CA23: 100 | CB23: 1.051667 | CC23: =INDEX($BZ:$BZ,MATCH(CA23,$BX:$BX,1)) -> 9167.5488 | CD23: =CC23/50 -CE$2 -> 183.38467 | CF23: 21 | CG23: 2 | CH23: 0.06593 | CI23: 250.80801 | CJ23: 100 | CK23: 1.065884 | CL23: =INDEX($CI:$CI,MATCH(CJ23,$CG:$CG,1)) -> 9315.0225 | CM23: =CL23/50 -CN$2 -> 186.33139 | CP23: 21 | CQ23: 2 | CR23: 0.0659 | CS23: 198.73399 | CT23: 100 | CU23: 1.053185 | CV23: =INDEX($CS:$CS,MATCH(CT23,$CQ:$CQ,1)) -> 9024.6455 | CW23: =CV23/50 -CX$2 -> 181.27715 | CY23: 21 | CZ23: 2 | DA23: 0.06589 | DB23: 238.37148 | DC23: 100 | DD23: 1.056221 | DE23: =INDEX($DB:$DB,MATCH(DC23,$CZ:$CZ,1)) -> 9113.6338 | DF23: =DE23/50 -DG$2 -> 182.31181 | DH23: 21 | DI23: 2 | DJ23: 0.0659 | DK23: 238.1541 | DL23: 100 | DM23: 1.053468 | DN23: =INDEX($DK:$DK,MATCH(DL23,$DI:$DI,1)) -> 9328.293 | DO23: =DN23/50 -DP$2 -> 186.62841 | DQ23: 21 | DR23: 2 | DS23: 0.0659 | DT23: 241.6111 | DU23: 100 | DV23: 1.059936 | DW23: =INDEX($DT:$DT,MATCH(DU23,$DR:$DR,1)) -> 9349.9072 | DX23: =DW23/50 -DY$2 -> 187.04819 | DZ23: 21 | EA23: 2 | EB23: 0.0659 | EC23: 242.77669 | ED23: 100 | EE23: 1.081097 | EF23: =INDEX($DT:$DT,MATCH(ED23,$DR:$DR,1)) -> 9349.9072 | EG23: =EF23/50 -EH$2 -> 187.04819
B24: 22 | C24: 2.1 | D24: 0.06924 | E24: 277.47162 | F24: 105 | G24: 1.102246 | H24: =INDEX($E:$E,MATCH(F24,$C:$C,1)) -> 9683.8223 | I24: =H24/50 -J$2 -> 193.67534 | K24: 22 | L24: 2.1 | M24: 0.06921 | N24: 264.31033 | O24: 105 | P24: 1.127675 | Q24: =INDEX($N:$N,MATCH(O24,$L:$L,1)) -> 9788.3574 | R24: =Q24/50 -S$2 -> 195.77049 | T24: 22 | U24: 2.1 | V24: 0.06929 | W24: 253.41075 | X24: 105 | Y24: 0.026445 | Z24: =INDEX($W:$W,MATCH(X24,$U:$U,1)) -> 5750.0772 | AA24: =Z24/50 -AB$2 -> 115.23904 | AC24: 22 | AD24: 2.1 | AE24: 0.06927 | AF24: 231.92424 | AG24: 105 | AH24: 1.130864 | AI24: =INDEX($AF:$AF,MATCH(AG24,$AD:$AD,1)) -> 9793.8311 | AJ24: =AI24/50 -AK$2 -> 196.48411 | AL24: 22 | AM24: 2.1 | AN24: 0.06921 | AO24: 254.76582 | AP24: 105 | AQ24: 1.136203 | AR24: =INDEX($AO:$AO,MATCH(AP24,$AM:$AM,1)) -> 9740.0996 | AS24: =AR24/50 -AT$2 -> 194.82218 | AV24: 22 | AW24: 2.1 | AX24: 0.06924 | AY24: 261.87747 | AZ24: 105 | BA24: 1.112785 | BB24: =INDEX($AY:$AY,MATCH(AZ24,$AW:$AW,1)) -> 9505.001 | BC24: =BB24/50 -BD$2 -> 190.10445 | BE24: 22 | BF24: 2.1 | BG24: 0.06927 | BH24: 252.29657 | BI24: 105 | BJ24: 2.935447 | BK24: =INDEX($BH:$BH,MATCH(BI24,$BF:$BF,1)) -> 5462.6602 | BL24: =BK24/50 -BM$2 -> 109.29541 | BN24: 22 | BO24: 2.1 | BP24: 0.06922 | BQ24: 224.00807 | BR24: 105 | BS24: 1.119263 | BT24: =INDEX($BQ:$BQ,MATCH(BR24,$BO:$BO,1)) -> 9704.0693 | BU24: =BT24/50 -BV$2 -> 194.79943 | BW24: 22 | BX24: 2.1 | BY24: 0.06925 | BZ24: 248.45647 | CA24: 105 | CB24: 1.102953 | CC24: =INDEX($BZ:$BZ,MATCH(CA24,$BX:$BX,1)) -> 9700.1113 | CD24: =CC24/50 -CE$2 -> 194.03592 | CF24: 22 | CG24: 2.1 | CH24: 0.06929 | CI24: 262.63898 | CJ24: 105 | CK24: 1.132169 | CL24: =INDEX($CI:$CI,MATCH(CJ24,$CG:$CG,1)) -> 9855.917 | CM24: =CL24/50 -CN$2 -> 197.14928 | CP24: 22 | CQ24: 2.1 | CR24: 0.06928 | CS24: 209.74486 | CT24: 105 | CU24: 1.115416 | CV24: =INDEX($CS:$CS,MATCH(CT24,$CQ:$CQ,1)) -> 9556.6562 | CW24: =CV24/50 -CX$2 -> 191.91736 | CY24: 22 | CZ24: 2.1 | DA24: 0.06922 | DB24: 248.76057 | DC24: 105 | DD24: 1.116348 | DE24: =INDEX($DB:$DB,MATCH(DC24,$CZ:$CZ,1)) -> 9622.4346 | DF24: =DE24/50 -DG$2 -> 192.48782 | DH24: 22 | DI24: 2.1 | DJ24: 0.06927 | DK24: 247.75232 | DL24: 105 | DM24: 1.112007 | DN24: =INDEX($DK:$DK,MATCH(DL24,$DI:$DI,1)) -> 9867.4502 | DO24: =DN24/50 -DP$2 -> 197.41155 | DQ24: 22 | DR24: 2.1 | DS24: 0.06923 | DT24: 253.12198 | DU24: 105 | DV24: 1.122373 | DW24: =INDEX($DT:$DT,MATCH(DU24,$DR:$DR,1)) -> 9894.2617 | DX24: =DW24/50 -DY$2 -> 197.93528 | DZ24: 22 | EA24: 2.1 | EB24: 0.06927 | EC24: 254.14288
B25: 23 | C25: 2.2 | D25: 0.07261 | E25: 289.62955 | K25: 23 | L25: 2.2 | M25: 0.0726 | N25: 274.89542 | O25: 110 | P25: 1.191946 | Q25: =INDEX($N:$N,MATCH(O25,$L:$L,1)) -> 10325.01 | R25: =Q25/50 -S$2 -> 206.50353 | T25: 23 | U25: 2.2 | V25: 0.07259 | W25: 263.02228 | AC25: 23 | AD25: 2.2 | AE25: 0.07256 | AF25: 241.91975 | AG25: 110 | AH25: 1.1957 | AI25: =INDEX($AF:$AF,MATCH(AG25,$AD:$AD,1)) -> 10328.756 | AJ25: =AI25/50 -AK$2 -> 207.1826 | AL25: 23 | AM25: 2.2 | AN25: 0.07261 | AO25: 266.02567 | AP25: 110 | AQ25: 1.186572 | AR25: =INDEX($AO:$AO,MATCH(AP25,$AM:$AM,1)) -> 10273.183 | AS25: =AR25/50 -AT$2 -> 205.48384 | AV25: 23 | AW25: 2.2 | AX25: 0.07259 | AY25: 272.56912 | AZ25: 110 | BA25: 1.179023 | BB25: =INDEX($AY:$AY,MATCH(AZ25,$AW:$AW,1)) -> 10028.754 | BC25: =BB25/50 -BD$2 -> 200.57951 | BE25: 23 | BF25: 2.2 | BG25: 0.07262 | BH25: 263.99966 | BN25: 23 | BO25: 2.2 | BP25: 0.07262 | BQ25: 234.5228 | BR25: 110 | BS25: 1.18992 | BT25: =INDEX($BQ:$BQ,MATCH(BR25,$BO:$BO,1)) -> 10203.148 | BU25: =BT25/50 -BV$2 -> 204.78102 | BW25: 23 | BX25: 2.2 | BY25: 0.07262 | BZ25: 258.46625 | CA25: 110 | CB25: -0.007184 | CC25: =INDEX($BZ:$BZ,MATCH(CA25,$BX:$BX,1)) -> 5812.4243 | CD25: =CC25/50 -CE$2 -> 116.28218 | CF25: 23 | CG25: 2.2 | CH25: 0.0726 | CI25: 272.73654 | CJ25: 110 | CK25: 3.212499 | CL25: =INDEX($CI:$CI,MATCH(CJ25,$CG:$CG,1)) -> 6047.8735 | CM25: =CL25/50 -CN$2 -> 120.98841 | CP25: 23 | CQ25: 2.2 | CR25: 0.0726 | CS25: 220.1817 | CT25: 110 | CU25: 1.178777 | CV25: =INDEX($CS:$CS,MATCH(CT25,$CQ:$CQ,1)) -> 10089.943 | CW25: =CV25/50 -CX$2 -> 202.5831 | CY25: 23 | CZ25: 2.2 | DA25: 0.0726 | DB25: 259.81824 | DC25: 110 | DD25: 1.173705 | DE25: =INDEX($DB:$DB,MATCH(DC25,$CZ:$CZ,1)) -> 10152.293 | DF25: =DE25/50 -DG$2 -> 203.08499 | DH25: 23 | DI25: 2.2 | DJ25: 0.0726 | DK25: 257.66476 | DL25: 110 | DM25: 1.171611 | DN25: =INDEX($DK:$DK,MATCH(DL25,$DI:$DI,1)) -> 10409.711 | DO25: =DN25/50 -DP$2 -> 208.25677 | DQ25: 23 | DR25: 2.2 | DS25: 0.0726 | DT25: 263.02664 | DU25: 110 | DV25: -0.00156 | DW25: =INDEX($DT:$DT,MATCH(DU25,$DR:$DR,1)) -> 6076.2993 | DX25: =DW25/50 -DY$2 -> 121.57603 | DZ25: 23 | EA25: 2.2 | EB25: 0.0726 | EC25: 264.19086
B26: 24 | C26: 2.3 | D26: 0.07592 | E26: 301.25412 | K26: 24 | L26: 2.3 | M26: 0.07594 | N26: 285.5126 | O26: 115 | P26: 0.009925 | Q26: =INDEX($N:$N,MATCH(O26,$L:$L,1)) -> 6074.9331 | R26: =Q26/50 -S$2 -> 121.502 | T26: 24 | U26: 2.3 | V26: 0.07587 | W26: 273.97549 | AC26: 24 | AD26: 2.3 | AE26: 0.07589 | AF26: 251.90965 | AL26: 24 | AM26: 2.3 | AN26: 0.07594 | AO26: 275.66003 | AP26: 115 | AQ26: 1.25204 | AR26: =INDEX($AO:$AO,MATCH(AP26,$AM:$AM,1)) -> 10808.016 | AS26: =AR26/50 -AT$2 -> 216.1805 | AV26: 24 | AW26: 2.3 | AX26: 0.07593 | AY26: 283.15805 | AZ26: 115 | BA26: 1.230335 | BB26: =INDEX($AY:$AY,MATCH(AZ26,$AW:$AW,1)) -> 10545.513 | BC26: =BB26/50 -BD$2 -> 210.91469 | BE26: 24 | BF26: 2.3 | BG26: 0.07591 | BH26: 274.0419 | BN26: 24 | BO26: 2.3 | BP26: 0.07593 | BQ26: 244.41106 | BR26: 115 | BS26: 3.343564 | BT26: =INDEX($BQ:$BQ,MATCH(BR26,$BO:$BO,1)) -> 10731.599 | BU26: =BT26/50 -BV$2 -> 215.35002 | BW26: 24 | BX26: 2.3 | BY26: 0.07592 | BZ26: 269.36877 | CF26: 24 | CG26: 2.3 | CH26: 0.0759 | CI26: 282.72156 | CP26: 24 | CQ26: 2.3 | CR26: 0.07595 | CS26: 230.57854 | CT26: 115 | CU26: 1.242447 | CV26: =INDEX($CS:$CS,MATCH(CT26,$CQ:$CQ,1)) -> 10629.616 | CW26: =CV26/50 -CX$2 -> 213.37656 | CY26: 24 | CZ26: 2.3 | DA26: 0.07592 | DB26: 269.77887 | DC26: 115 | DD26: 3.411887 | DE26: =INDEX($DB:$DB,MATCH(DC26,$CZ:$CZ,1)) -> 6064.6982 | DF26: =DE26/50 -DG$2 -> 121.3331 | DH26: 24 | DI26: 2.3 | DJ26: 0.07594 | DK26: 268.56705 | DL26: 115 | DM26: 1.233987 | DN26: =INDEX($DK:$DK,MATCH(DL26,$DI:$DI,1)) -> 10957.724 | DO26: =DN26/50 -DP$2 -> 219.21702 | DQ26: 24 | DR26: 2.3 | DS26: 0.07593 | DT26: 273.1936 | DZ26: 24 | EA26: 2.3 | EB26: 0.07594 | EC26: 275.19839
B27: 25 | C27: 2.4 | D27: 0.07918 | E27: 313.45651 | K27: 25 | L27: 2.4 | M27: 0.07924 | N27: 295.97406 | T27: 25 | U27: 2.4 | V27: 0.07925 | W27: 284.9877 | AC27: 25 | AD27: 2.4 | AE27: 0.07926 | AF27: 263.10254 | AL27: 25 | AM27: 2.4 | AN27: 0.07924 | AO27: 285.47461 | AP27: 120 | AQ27: 3.297278 | AR27: =INDEX($AO:$AO,MATCH(AP27,$AM:$AM,1)) -> 6338.5649 | AS27: =AR27/50 -AT$2 -> 126.79149 | AV27: 25 | AW27: 2.4 | AX27: 0.07921 | AY27: 294.44568 | AZ27: 120 | BA27: 3.36671 | BB27: =INDEX($AY:$AY,MATCH(AZ27,$AW:$AW,1)) -> 6184.8306 | BC27: =BB27/50 -BD$2 -> 123.70105 | BE27: 25 | BF27: 2.4 | BG27: 0.07926 | BH27: 284.60559 | BN27: 25 | BO27: 2.4 | BP27: 0.07922 | BQ27: 255.09328 | BW27: 25 | BX27: 2.4 | BY27: 0.07925 | BZ27: 279.38562 | CF27: 25 | CG27: 2.4 | CH27: 0.07927 | CI27: 294.67175 | CP27: 25 | CQ27: 2.4 | CR27: 0.07929 | CS27: 239.67125 | CT27: 120 | CU27: 1.301746 | CV27: =INDEX($CS:$CS,MATCH(CT27,$CQ:$CQ,1)) -> 11104.372 | CW27: =CV27/50 -CX$2 -> 222.87168 | CY27: 25 | CZ27: 2.4 | DA27: 0.07928 | DB27: 280.79828 | DH27: 25 | DI27: 2.4 | DJ27: 0.07928 | DK27: 279.37357 | DL27: 120 | DM27: 3.469984 | DN27: =INDEX($DK:$DK,MATCH(DL27,$DI:$DI,1)) -> 6763.1567 | DO27: =DN27/50 -DP$2 -> 135.32568 | DQ27: 25 | DR27: 2.4 | DS27: 0.07928 | DT27: 284.16791 | DZ27: 25 | EA27: 2.4 | EB27: 0.07928 | EC27: 285.94159
B28: 26 | C28: 2.5 | D28: 0.08261 | E28: 325.03586 | K28: 26 | L28: 2.5 | M28: 0.08263 | N28: 306.27176 | T28: 26 | U28: 2.5 | V28: 0.08256 | W28: 295.77036 | AC28: 26 | AD28: 2.5 | AE28: 0.08257 | AF28: 273.09042 | AL28: 26 | AM28: 2.5 | AN28: 0.08262 | AO28: 296.05731 | AV28: 26 | AW28: 2.5 | AX28: 0.08258 | AY28: 304.40085 | BE28: 26 | BF28: 2.5 | BG28: 0.08259 | BH28: 294.97052 | BN28: 26 | BO28: 2.5 | BP28: 0.08258 | BQ28: 265.11041 | BW28: 26 | BX28: 2.5 | BY28: 0.08262 | BZ28: 289.9241 | CF28: 26 | CG28: 2.5 | CH28: 0.08256 | CI28: 304.63782 | CP28: 26 | CQ28: 2.5 | CR28: 0.08258 | CS28: 250.31035 | CT28: 125 | CU28: 3.627347 | CV28: =INDEX($CS:$CS,MATCH(CT28,$CQ:$CQ,1)) -> 6620.8779 | CW28: =CV28/50 -CX$2 -> 133.2018 | CY28: 26 | CZ28: 2.5 | DA28: 0.08261 | DB28: 290.71286 | DH28: 26 | DI28: 2.5 | DJ28: 0.08258 | DK28: 289.89987 | DQ28: 26 | DR28: 2.5 | DS28: 0.08261 | DT28: 294.22198 | DZ28: 26 | EA28: 2.5 | EB28: 0.08258 | EC28: 295.73569
B29: 27 | C29: 2.6 | D29: 0.08593 | E29: 336.77124 | K29: 27 | L29: 2.6 | M29: 0.08595 | N29: 317.10126 | T29: 27 | U29: 2.6 | V29: 0.08587 | W29: 305.9765 | AC29: 27 | AD29: 2.6 | AE29: 0.0859 | AF29: 283.30524 | AL29: 27 | AM29: 2.6 | AN29: 0.08592 | AO29: 306.10229 | AV29: 27 | AW29: 2.6 | AX29: 0.08595 | AY29: 314.99844 | BE29: 27 | BF29: 2.6 | BG29: 0.08588 | BH29: 305.01746 | BN29: 27 | BO29: 2.6 | BP29: 0.08592 | BQ29: 275.73364 | BW29: 27 | BX29: 2.6 | BY29: 0.08592 | BZ29: 299.89136 | CF29: 27 | CG29: 2.6 | CH29: 0.08589 | CI29: 314.86108 | CP29: 27 | CQ29: 2.6 | CR29: 0.0859 | CS29: 260.37183 | CY29: 27 | CZ29: 2.6 | DA29: 0.08589 | DB29: 300.57599 | DH29: 27 | DI29: 2.6 | DJ29: 0.08589 | DK29: 299.84769 | DQ29: 27 | DR29: 2.6 | DS29: 0.0859 | DT29: 304.25253 | DZ29: 27 | EA29: 2.6 | EB29: 0.08589 | EC29: 306.24826
B30: 28 | C30: 2.7 | D30: 0.08922 | E30: 348.57288 | K30: 28 | L30: 2.7 | M30: 0.08923 | N30: 327.13965 | T30: 28 | U30: 2.7 | V30: 0.0893 | W30: 316.96628 | AC30: 28 | AD30: 2.7 | AE30: 0.08929 | AF30: 294.78482 | AL30: 28 | AM30: 2.7 | AN30: 0.08919 | AO30: 316.35016 | AV30: 28 | AW30: 2.7 | AX30: 0.08924 | AY30: 325.69254 | BE30: 28 | BF30: 2.7 | BG30: 0.08925 | BH30: 315.20193 | BN30: 28 | BO30: 2.7 | BP30: 0.08921 | BQ30: 286.07419 | BW30: 28 | BX30: 2.7 | BY30: 0.08922 | BZ30: 309.49152 | CF30: 28 | CG30: 2.7 | CH30: 0.08927 | CI30: 325.76013 | CP30: 28 | CQ30: 2.7 | CR30: 0.08925 | CS30: 270.44901 | CY30: 28 | CZ30: 2.7 | DA30: 0.08923 | DB30: 311.02402 | DH30: 28 | DI30: 2.7 | DJ30: 0.08925 | DK30: 310.80222 | DQ30: 28 | DR30: 2.7 | DS30: 0.08924 | DT30: 315.19098 | DZ30: 28 | EA30: 2.7 | EB30: 0.08925 | EC30: 317.20822
B31: 29 | C31: 2.8 | D31: 0.09263 | E31: 360.25153 | K31: 29 | L31: 2.8 | M31: 0.09258 | N31: 337.59195 | T31: 29 | U31: 2.8 | V31: 0.09262 | W31: 327.78159 | AC31: 29 | AD31: 2.8 | AE31: 0.09261 | AF31: 305.01233 | AL31: 29 | AM31: 2.8 | AN31: 0.09257 | AO31: 327.50131 | AV31: 29 | AW31: 2.8 | AX31: 0.09258 | AY31: 336.10123 | BE31: 29 | BF31: 2.8 | BG31: 0.09258 | BH31: 326.06519 | BN31: 29 | BO31: 2.8 | BP31: 0.0926 | BQ31: 296.82318 | BW31: 29 | BX31: 2.8 | BY31: 0.09257 | BZ31: 321.11963 | CF31: 29 | CG31: 2.8 | CH31: 0.09259 | CI31: 336.43814 | CP31: 29 | CQ31: 2.8 | CR31: 0.09259 | CS31: 279.55588 | CY31: 29 | CZ31: 2.8 | DA31: 0.09259 | DB31: 321.46231 | DH31: 29 | DI31: 2.8 | DJ31: 0.09259 | DK31: 320.40945 | DQ31: 29 | DR31: 2.8 | DS31: 0.09259 | DT31: 325.40878 | DZ31: 29 | EA31: 2.8 | EB31: 0.09259 | EC31: 327.46072
B32: 30 | C32: 2.9 | D32: 0.0959 | E32: 371.97263 | K32: 30 | L32: 2.9 | M32: 0.0959 | N32: 347.91412 | T32: 30 | U32: 2.9 | V32: 0.0959 | W32: 338.38174 | AC32: 30 | AD32: 2.9 | AE32: 0.09593 | AF32: 315.48477 | AL32: 30 | AM32: 2.9 | AN32: 0.09591 | AO32: 337.74997 | AV32: 30 | AW32: 2.9 | AX32: 0.09593 | AY32: 346.93857 | BE32: 30 | BF32: 2.9 | BG32: 0.0959 | BH32: 336.08063 | BN32: 30 | BO32: 2.9 | BP32: 0.09594 | BQ32: 307.20551 | BW32: 30 | BX32: 2.9 | BY32: 0.09591 | BZ32: 330.98318 | CF32: 30 | CG32: 2.9 | CH32: 0.09594 | CI32: 347.48087 | CP32: 30 | CQ32: 2.9 | CR32: 0.09591 | CS32: 290.19574 | CY32: 30 | CZ32: 2.9 | DA32: 0.09589 | DB32: 331.57346 | DH32: 30 | DI32: 2.9 | DJ32: 0.0959 | DK32: 330.8837 | DQ32: 30 | DR32: 2.9 | DS32: 0.0959 | DT32: 335.5722 | DZ32: 30 | EA32: 2.9 | EB32: 0.0959 | EC32: 337.43008
B33: 31 | C33: 3 | D33: 0.09921 | E33: 383.37497 | K33: 31 | L33: 3 | M33: 0.09923 | N33: 358.47208 | T33: 31 | U33: 3 | V33: 0.09928 | W33: 348.9581 | AC33: 31 | AD33: 3 | AE33: 0.09927 | AF33: 325.17435 | AL33: 31 | AM33: 3 | AN33: 0.09922 | AO33: 347.19717 | AV33: 31 | AW33: 3 | AX33: 0.09923 | AY33: 357.61319 | BE33: 31 | BF33: 3 | BG33: 0.09928 | BH33: 346.22141 | BN33: 31 | BO33: 3 | BP33: 0.09923 | BQ33: 317.0188 | BW33: 31 | BX33: 3 | BY33: 0.09927 | BZ33: 342.08044 | CF33: 31 | CG33: 3 | CH33: 0.09927 | CI33: 357.56653 | CP33: 31 | CQ33: 3 | CR33: 0.09927 | CS33: 299.97427 | CY33: 31 | CZ33: 3 | DA33: 0.09923 | DB33: 341.89386 | DH33: 31 | DI33: 3 | DJ33: 0.09927 | DK33: 341.49619 | DQ33: 31 | DR33: 3 | DS33: 0.09924 | DT33: 345.96066 | DZ33: 31 | EA33: 3 | EB33: 0.09926 | EC33: 346.98782
B34: 32 | C34: 3.1 | D34: 0.10261 | E34: 394.87189 | K34: 32 | L34: 3.1 | M34: 0.1026 | N34: 368.5686 | T34: 32 | U34: 3.1 | V34: 0.1026 | W34: 359.67438 | AC34: 32 | AD34: 3.1 | AE34: 0.10257 | AF34: 335.88785 | AL34: 32 | AM34: 3.1 | AN34: 0.10262 | AO34: 357.40533 | AV34: 32 | AW34: 3.1 | AX34: 0.10259 | AY34: 368.18402 | BE34: 32 | BF34: 3.1 | BG34: 0.10263 | BH34: 357.12662 | BN34: 32 | BO34: 3.1 | BP34: 0.10263 | BQ34: 328.45609 | BW34: 32 | BX34: 3.1 | BY34: 0.10261 | BZ34: 351.54581 | CF34: 32 | CG34: 3.1 | CH34: 0.10255 | CI34: 368.24057 | CP34: 32 | CQ34: 3.1 | CR34: 0.1026 | CS34: 309.72159 | CY34: 32 | CZ34: 3.1 | DA34: 0.10261 | DB34: 351.14743 | DH34: 32 | DI34: 3.1 | DJ34: 0.1026 | DK34: 351.35278 | DQ34: 32 | DR34: 3.1 | DS34: 0.10262 | DT34: 356.02261 | DZ34: 32 | EA34: 3.1 | EB34: 0.1026 | EC34: 357.86649
B35: 33 | C35: 3.2 | D35: 0.10591 | E35: 405.69235 | K35: 33 | L35: 3.2 | M35: 0.10593 | N35: 379.42499 | T35: 33 | U35: 3.2 | V35: 0.10588 | W35: 370.03491 | AC35: 33 | AD35: 3.2 | AE35: 0.1059 | AF35: 345.56427 | AL35: 33 | AM35: 3.2 | AN35: 0.10595 | AO35: 367.08914 | AV35: 33 | AW35: 3.2 | AX35: 0.1059 | AY35: 378.14481 | BE35: 33 | BF35: 3.2 | BG35: 0.10592 | BH35: 366.58264 | BN35: 33 | BO35: 3.2 | BP35: 0.10596 | BQ35: 337.97052 | BW35: 33 | BX35: 3.2 | BY35: 0.10592 | BZ35: 361.1398 | CF35: 33 | CG35: 3.2 | CH35: 0.10588 | CI35: 377.7558 | CP35: 33 | CQ35: 3.2 | CR35: 0.1059 | CS35: 319.34518 | CY35: 33 | CZ35: 3.2 | DA35: 0.10591 | DB35: 361.65546 | DH35: 33 | DI35: 3.2 | DJ35: 0.10589 | DK35: 360.90775 | DQ35: 33 | DR35: 3.2 | DS35: 0.10592 | DT35: 366.00079 | DZ35: 33 | EA35: 3.2 | EB35: 0.10589 | EC35: 367.97485
B36: 34 | C36: 3.3 | D36: 0.10922 | E36: 417.45227 | K36: 34 | L36: 3.3 | M36: 0.10924 | N36: 389.51315 | T36: 34 | U36: 3.3 | V36: 0.10927 | W36: 379.73904 | AC36: 34 | AD36: 3.3 | AE36: 0.10926 | AF36: 356.30786 | AL36: 34 | AM36: 3.3 | AN36: 0.10925 | AO36: 377.23846 | AV36: 34 | AW36: 3.3 | AX36: 0.10925 | AY36: 388.87247 | BE36: 34 | BF36: 3.3 | BG36: 0.10925 | BH36: 377.01892 | BN36: 34 | BO36: 3.3 | BP36: 0.1092 | BQ36: 347.60049 | BW36: 34 | BX36: 3.3 | BY36: 0.10924 | BZ36: 372.00717 | CF36: 34 | CG36: 3.3 | CH36: 0.10924 | CI36: 388.99207 | CP36: 34 | CQ36: 3.3 | CR36: 0.10924 | CS36: 329.6767 | CY36: 34 | CZ36: 3.3 | DA36: 0.10922 | DB36: 371.21234 | DH36: 34 | DI36: 3.3 | DJ36: 0.10924 | DK36: 371.73453 | DQ36: 34 | DR36: 3.3 | DS36: 0.10923 | DT36: 376.02219 | DZ36: 34 | EA36: 3.3 | EB36: 0.10924 | EC36: 378.66992
B37: 35 | C37: 3.4 | D37: 0.11262 | E37: 428.08774 | K37: 35 | L37: 3.4 | M37: 0.1126 | N37: 399.3067 | T37: 35 | U37: 3.4 | V37: 0.11258 | W37: 391.0376 | AC37: 35 | AD37: 3.4 | AE37: 0.11259 | AF37: 366.46924 | AL37: 35 | AM37: 3.4 | AN37: 0.11261 | AO37: 387.36362 | AV37: 35 | AW37: 3.4 | AX37: 0.1126 | AY37: 399.9234 | BE37: 35 | BF37: 3.4 | BG37: 0.11259 | BH37: 387.01169 | BN37: 35 | BO37: 3.4 | BP37: 0.11259 | BQ37: 358.39587 | BW37: 35 | BX37: 3.4 | BY37: 0.11258 | BZ37: 381.22629 | CF37: 35 | CG37: 3.4 | CH37: 0.11257 | CI37: 399.95474 | CP37: 35 | CQ37: 3.4 | CR37: 0.11258 | CS37: 339.08447 | CY37: 35 | CZ37: 3.4 | DA37: 0.11257 | DB37: 381.81607 | DH37: 35 | DI37: 3.4 | DJ37: 0.11257 | DK37: 381.03525 | DQ37: 35 | DR37: 3.4 | DS37: 0.11258 | DT37: 385.70871 | DZ37: 35 | EA37: 3.4 | EB37: 0.11257 | EC37: 387.91382
B38: 36 | C38: 3.5 | D38: 0.11594 | E38: 438.48935 | K38: 36 | L38: 3.5 | M38: 0.11591 | N38: 409.58014 | T38: 36 | U38: 3.5 | V38: 0.11591 | W38: 401.1951 | AC38: 36 | AD38: 3.5 | AE38: 0.11591 | AF38: 377.2218 | AL38: 36 | AM38: 3.5 | AN38: 0.11593 | AO38: 397.89435 | AV38: 36 | AW38: 3.5 | AX38: 0.11595 | AY38: 409.95407 | BE38: 36 | BF38: 3.5 | BG38: 0.11588 | BH38: 397.61462 | BN38: 36 | BO38: 3.5 | BP38: 0.11593 | BQ38: 368.07907 | BW38: 36 | BX38: 3.5 | BY38: 0.11588 | BZ38: 391.62598 | CF38: 36 | CG38: 3.5 | CH38: 0.11591 | CI38: 409.29419 | CP38: 36 | CQ38: 3.5 | CR38: 0.11589 | CS38: 348.74188 | CY38: 36 | CZ38: 3.5 | DA38: 0.11589 | DB38: 391.07767 | DH38: 36 | DI38: 3.5 | DJ38: 0.11589 | DK38: 391.40259 | DQ38: 36 | DR38: 3.5 | DS38: 0.11589 | DT38: 396.3255 | DZ38: 36 | EA38: 3.5 | EB38: 0.11589 | EC38: 397.9635
B39: 37 | C39: 3.6 | D39: 0.11925 | E39: 449.9277 | K39: 37 | L39: 3.6 | M39: 0.1192 | N39: 419.35355 | T39: 37 | U39: 3.6 | V39: 0.1193 | W39: 411.41196 | AC39: 37 | AD39: 3.6 | AE39: 0.11929 | AF39: 386.99487 | AL39: 37 | AM39: 3.6 | AN39: 0.11922 | AO39: 406.66602 | AV39: 37 | AW39: 3.6 | AX39: 0.11927 | AY39: 420.37369 | BE39: 37 | BF39: 3.6 | BG39: 0.11924 | BH39: 407.18875 | BN39: 37 | BO39: 3.6 | BP39: 0.11922 | BQ39: 377.66995 | BW39: 37 | BX39: 3.6 | BY39: 0.11922 | BZ39: 401.20898 | CF39: 37 | CG39: 3.6 | CH39: 0.11928 | CI39: 420.78543 | CP39: 37 | CQ39: 3.6 | CR39: 0.11928 | CS39: 358.48422 | CY39: 37 | CZ39: 3.6 | DA39: 0.11922 | DB39: 401.14853 | DH39: 37 | DI39: 3.6 | DJ39: 0.11927 | DK39: 401.45508 | DQ39: 37 | DR39: 3.6 | DS39: 0.11923 | DT39: 407.25067 | DZ39: 37 | EA39: 3.6 | EB39: 0.11927 | EC39: 408.50854
B40: 38 | C40: 3.7 | D40: 0.12261 | E40: 460.3605 | K40: 38 | L40: 3.7 | M40: 0.12256 | N40: 429.63422 | T40: 38 | U40: 3.7 | V40: 0.12258 | W40: 421.51523 | AC40: 38 | AD40: 3.7 | AE40: 0.1226 | AF40: 397.21622 | AL40: 38 | AM40: 3.7 | AN40: 0.12259 | AO40: 416.6918 | AV40: 38 | AW40: 3.7 | AX40: 0.12258 | AY40: 430.02026 | BE40: 38 | BF40: 3.7 | BG40: 0.1226 | BH40: 416.91357 | BN40: 38 | BO40: 3.7 | BP40: 0.1226 | BQ40: 387.66809 | BW40: 38 | BX40: 3.7 | BY40: 0.1226 | BZ40: 411.39307 | CF40: 38 | CG40: 3.7 | CH40: 0.12261 | CI40: 430.07242 | CP40: 38 | CQ40: 3.7 | CR40: 0.12262 | CS40: 368.59808 | CY40: 38 | CZ40: 3.7 | DA40: 0.12259 | DB40: 410.36472 | DH40: 38 | DI40: 3.7 | DJ40: 0.12261 | DK40: 411.67963 | DQ40: 38 | DR40: 3.7 | DS40: 0.1226 | DT40: 417.34283 | DZ40: 38 | EA40: 3.7 | EB40: 0.12261 | EC40: 418.99036
... B1017: 1015 | C1017: 101.4 | D1017: 3.37929 | E1017: 9300.7588 | K1017: 1015 | L1017: 101.4 | M1017: 3.37927 | N1017: 9431.5215 | T1017: 1015 | U1017: 101.4 | V1017: 3.37924 | W1017: 9590.0742 | AC1017: 1015 | AD1017: 101.4 | AE1017: 3.37927 | AF1017: 9409.8887 | AL1017: 1015 | AM1017: 101.4 | AN1017: 3.37926 | AO1017: 9358.2363 | AV1017: 1015 | AW1017: 101.4 | AX1017: 3.37927 | AY1017: 9129.0967 | BE1017: 1015 | BF1017: 101.4 | BG1017: 3.37921 | BH1017: 9290.1104 | BN1017: 1015 | BO1017: 101.4 | BP1017: 3.37924 | BQ1017: 9323.9014 | BW1017: 1015 | BX1017: 101.4 | BY1017: 3.37927 | BZ1017: 9316.0361 | CF1017: 1015 | CG1017: 101.4 | CH1017: 3.3792 | CI1017: 9464.8486 | CP1017: 1015 | CQ1017: 101.4 | CR1017: 3.37922 | CS1017: 9173.5449 | CY1017: 1015 | CZ1017: 101.4 | DA1017: 3.37925 | DB1017: 9261.5479 | DH1017: 1015 | DI1017: 101.4 | DJ1017: 3.37922 | DK1017: 9478.4736 | DQ1017: 1015 | DR1017: 101.4 | DS1017: 3.37926 | DT1017: 9501.8896 | DZ1017: 1015 | EA1017: 100.906 | EB1017: 3.36286 | EC1017: 5648.1392
B1018: 1016 | C1018: 101.5 | D1018: 3.38258 | E1018: 9311.5322 | K1018: 1016 | L1018: 101.5 | M1018: 3.38257 | N1018: 9441.8223 | T1018: 1016 | U1018: 101.5 | V1018: 3.38258 | W1018: 9600.9609 | AC1018: 1016 | AD1018: 101.5 | AE1018: 3.38262 | AF1018: 9420.2559 | AL1018: 1016 | AM1018: 101.5 | AN1018: 3.38256 | AO1018: 9368.1797 | AV1018: 1016 | AW1018: 101.5 | AX1018: 3.38254 | AY1018: 9138.9922 | BE1018: 1016 | BF1018: 101.5 | BG1018: 3.38257 | BH1018: 9300.8584 | BN1018: 1016 | BO1018: 101.5 | BP1018: 3.38254 | BQ1018: 9333.96 | BW1018: 1016 | BX1018: 101.5 | BY1018: 3.38254 | BZ1018: 9327.1016 | CF1018: 1016 | CG1018: 101.5 | CH1018: 3.38261 | CI1018: 9477.041 | CP1018: 1016 | CQ1018: 101.5 | CR1018: 3.38258 | CS1018: 9184.1846 | CY1018: 1016 | CZ1018: 101.5 | DA1018: 3.38256 | DB1018: 9271.9023 | DH1018: 1016 | DI1018: 101.5 | DJ1018: 3.38257 | DK1018: 9489.6973 | DQ1018: 1016 | DR1018: 101.5 | DS1018: 3.38256 | DT1018: 9512.7822
B1019: 1017 | C1019: 101.6 | D1019: 3.38592 | E1019: 9322.293 | K1019: 1017 | L1019: 101.6 | M1019: 3.38593 | N1019: 9452.9717 | T1019: 1017 | U1019: 101.6 | V1019: 3.38591 | W1019: 9611.7373 | AC1019: 1017 | AD1019: 101.6 | AE1019: 3.38592 | AF1019: 9430.5088 | AL1019: 1017 | AM1019: 101.6 | AN1019: 3.38592 | AO1019: 9379.1231 | AV1019: 1017 | AW1019: 101.6 | AX1019: 3.38593 | AY1019: 9150.5898 | BE1019: 1017 | BF1019: 101.6 | BG1019: 3.38591 | BH1019: 9311.0644 | BN1019: 1017 | BO1019: 101.6 | BP1019: 3.3859 | BQ1019: 9345.0312 | BW1019: 1017 | BX1019: 101.6 | BY1019: 3.38594 | BZ1019: 9337.2832 | CF1019: 1017 | CG1019: 101.6 | CH1019: 3.38594 | CI1019: 9487.0947 | CP1019: 1017 | CQ1019: 101.6 | CR1019: 3.3859 | CS1019: 9194.7021 | CY1019: 1017 | CZ1019: 101.6 | DA1019: 3.38591 | DB1019: 9283.1709 | DH1019: 1017 | DI1019: 101.6 | DJ1019: 3.3859 | DK1019: 9500.5781 | DQ1019: 1017 | DR1019: 101.6 | DS1019: 3.38591 | DT1019: 9523.8203
B1020: 1018 | C1020: 101.7 | D1020: 3.38923 | E1020: 9332.4824 | K1020: 1018 | L1020: 101.7 | M1020: 3.38926 | N1020: 9463.6709 | T1020: 1018 | U1020: 101.7 | V1020: 3.38926 | W1020: 9623.085 | AC1020: 1018 | AD1020: 101.7 | AE1020: 3.38923 | AF1020: 9441.6025 | AL1020: 1018 | AM1020: 101.7 | AN1020: 3.38923 | AO1020: 9390.4727 | AV1020: 1018 | AW1020: 101.7 | AX1020: 3.38927 | AY1020: 9160.2842 | BE1020: 1018 | BF1020: 101.7 | BG1020: 3.3892 | BH1020: 9321.5918 | BN1020: 1018 | BO1020: 101.7 | BP1020: 3.38926 | BQ1020: 9355.667 | BW1020: 1018 | BX1020: 101.7 | BY1020: 3.38926 | BZ1020: 9348.3486 | CF1020: 1018 | CG1020: 101.7 | CH1020: 3.38921 | CI1020: 9497.793 | CP1020: 1018 | CQ1020: 101.7 | CR1020: 3.38926 | CS1020: 9205.0986 | CY1020: 1018 | CZ1020: 101.7 | DA1020: 3.3892 | DB1020: 9293.1709 | DH1020: 1018 | DI1020: 101.7 | DJ1020: 3.38926 | DK1020: 9511.6191 | DQ1020: 1018 | DR1020: 101.7 | DS1020: 3.38921 | DT1020: 9534.0674
B1021: 1019 | C1021: 101.8 | D1021: 3.39257 | E1021: 9344.1123 | K1021: 1019 | L1021: 101.8 | M1021: 3.39254 | N1021: 9473.7519 | T1021: 1019 | U1021: 101.8 | V1021: 3.39263 | W1021: 9633.8945 | AC1021: 1019 | AD1021: 101.8 | AE1021: 3.39262 | AF1021: 9452.6455 | AL1021: 1019 | AM1021: 101.8 | AN1021: 3.39254 | AO1021: 9400.2744 | AV1021: 1019 | AW1021: 101.8 | AX1021: 3.39255 | AY1021: 9170.0215 | BE1021: 1019 | BF1021: 101.8 | BG1021: 3.3926 | BH1021: 9332.3643 | BN1021: 1019 | BO1021: 101.8 | BP1021: 3.3926 | BQ1021: 9366.7481 | BW1021: 1019 | BX1021: 101.8 | BY1021: 3.39255 | BZ1021: 9358.9004 | CF1021: 1019 | CG1021: 101.8 | CH1021: 3.39262 | CI1021: 9509.041 | CP1021: 1019 | CQ1021: 101.8 | CR1021: 3.39262 | CS1021: 9216.21 | CY1021: 1019 | CZ1021: 101.8 | DA1021: 3.3926 | DB1021: 9304.6748 | DH1021: 1019 | DI1021: 101.8 | DJ1021: 3.39261 | DK1021: 9522.1211 | DQ1021: 1019 | DR1021: 101.8 | DS1021: 3.39261 | DT1021: 9544.9248
B1022: 1020 | C1022: 101.9 | D1022: 3.3959 | E1022: 9354.8106 | K1022: 1020 | L1022: 101.9 | M1022: 3.39591 | N1022: 9484.5703 | T1022: 1020 | U1022: 101.9 | V1022: 3.39592 | W1022: 9643.5371 | AC1022: 1020 | AD1022: 101.9 | AE1022: 3.39593 | AF1022: 9463.6006 | AL1022: 1020 | AM1022: 101.9 | AN1022: 3.39593 | AO1022: 9411.2852 | AV1022: 1020 | AW1022: 101.9 | AX1022: 3.39591 | AY1022: 9180.8711 | BE1022: 1020 | BF1022: 101.9 | BG1022: 3.39595 | BH1022: 9341.585 | BN1022: 1020 | BO1022: 101.9 | BP1022: 3.39594 | BQ1022: 9376.6826 | BW1022: 1020 | BX1022: 101.9 | BY1022: 3.39592 | BZ1022: 9369.71 | CF1022: 1020 | CG1022: 101.9 | CH1022: 3.39594 | CI1022: 9520.2969 | CP1022: 1020 | CQ1022: 101.9 | CR1022: 3.39594 | CS1022: 9226.1543 | CY1022: 1020 | CZ1022: 101.9 | DA1022: 3.39594 | DB1022: 9314.9209 | DH1022: 1020 | DI1022: 101.9 | DJ1022: 3.39593 | DK1022: 9532.2236 | DQ1022: 1020 | DR1022: 101.9 | DS1022: 3.39595 | DT1022: 9556.0879
